Workbook
Name Rok: Ustawienia!$B$3
Name Miesiac: Ustawienia!$B$4
Name DniMiesiaca: Ustawienia!$B$5
Name ListaZmian: Ustawienia!$A$8:$A$10
Name ListaUderzen: OFFSET(Ustawienia!$D$4,0,0,MAX(1,COUNTA(Ustawienia!$D$4:$D$33)),1)
Name ListaCzesci: OFFSET(Ustawienia!$F$4,0,0,MAX(1,COUNTA(Ustawienia!$F$4:$F$33)),1)
Name ListaKiedy: OFFSET(Ustawienia!$H$4,0,0,MAX(1,COUNTA(Ustawienia!$H$4:$H$13)),1)
Name ListaStatusow: Ustawienia!$J$4:$J$8
Name TakNie: Ustawienia!$M$4:$M$5
Name ListaPracownikow: OFFSET(Pracownicy!$A$2,0,0,MAX(1,COUNTA(Pracownicy!$A$2:$A$2000)),1)
Name ListaWozkow: OFFSET('Wózki'!$A$2,0,0,MAX(1,COUNTA('Wózki'!$A$2:$A$500)),1)

Sheet Instrukcja
A1: REJESTR USZKODZEŃ WÓZKÓW — wersja Excel
A2: Ten sam układ co aplikacja: Flota, Zgłoszenia, Rozpiska (arkusze 1–31), Historia wózka.
A5: Na start
A6: 1. | B6: Ustawienia: wpisz rok i miesiąc. Arkusze 1–31 pokażą daty i dni tygodnia tego miesiąca (w krótszych miesiącach arkusze 29–31 będą puste).
A7: 2. | B7: Pracownicy i Wózki: zastąp przykładowe wpisy własną listą (można wkleić kolumny z Excela). Z tych list biorą się rozwijane listy.
A8: 3. | B8: Ustawienia: rodzaje uderzeń, części, nazwy zmian i stanowisk — jak w aplikacji.
A10: Na co dzień
A11: Arkusze 1–31 | B11: Rozpiska na dany dzień: zmiana I, II i III obok siebie. Wpisz osobę, wózek i uwagi. Czerwone pole wózka = wózek wpisany dwa razy na tej zmianie albo wyłączony z pracy (otwarte zgłoszenie). Żółte nazwisko = osoba wpisana dwa razy.
A12: Zgłoszenia | B12: Jeden wiersz = jedno zgłoszenie. Status zmieniasz z listy. „Wyłączony z pracy” = TAK blokuje wózek na Flocie i w rozpisce. Kolumna „Wg rozpiski” sama pokazuje, kto miał ten wózek tego dnia.
A13: Flota | B13: Stan każdego wózka liczony ze zgłoszeń: Sprawny / Usterka zgłoszona / W naprawie / Wyłączony z pracy.
A14: Historia wózka | B14: Wybierz wózek i okres: najpierw usterki i uszkodzenia, niżej kto jeździł (z rozpisek). Wydruk obejmuje tylko wypełnione wiersze.
A15: Drukowanie | B15: Arkusz dnia: każda zmiana drukuje się na osobnej stronie A4. Plik nie ma nagłówków ani stopek z adresem.
A17: Kolory
A18: Żółte pola | B18: wypełniasz Ty. Białe pola liczą się same z formuł — nie nadpisuj ich.
A19: Dane rozpisek | B19: arkusz pomocniczy na końcu: zbiera wpisy ze wszystkich dni. Nie wpisuj tam nic.
A20: Nowy miesiąc | B20: Zapisz plik jako kopię (np. Rozpiska 11.2026.xlsx), w kopii zmień miesiąc w Ustawieniach i wyczyść arkusze 1–31.
A21: Przykład | B21: W pliku jest jedno przykładowe zgłoszenie (wózek 105) i jeden wpis w rozpisce dnia 1 — usuń je przed użyciem.
A23: Żółte pole | B23: – do wypełnienia

Sheet Flota
A1: STAN WÓZKÓW
A2: Liczone na żywo ze zgłoszeń. Lista wózków: arkusz Wózki. | G2: =7+MAX(1,COUNTA('Wózki'!$A$2:$A$500))
A4: =COUNTIF($C$8:$C$207,"Sprawny") | B4: =COUNTIF($C$8:$C$207,"Usterka zgłoszona") | C4: =COUNTIF($C$8:$C$207,"W naprawie") | D4: =COUNTIF($C$8:$C$207,"Wyłączony z pracy")
A5: Sprawne | B5: Usterka zgłoszona | C5: W naprawie | D5: Wyłączone z pracy
A7: Nr wózka | B7: Typ | C7: Stan | D7: Otwarte usterki | E7: Ostatnia otwarta usterka
A8: =IF('Wózki'!A2="","",'Wózki'!A2) | B8: =IF(A8="","",'Wózki'!B2&"") | C8: =IF(A8="","",IF(COUNTIFS('Zgłoszenia'!$B$5:$B$504,A8,'Zgłoszenia'!$O$5:$O$504,"TAK",'Zgłoszenia'!$L$5:$L$504,"TAK")>0,"Wyłączony z pracy",IF(COUNTIFS('Zgłoszenia'!$B$5:$B$504,A8,'Zgłoszenia'!$M$5:$M$504,Ustawienia!$J$5)+COUNTIFS('Zgłoszenia'!$B$5:$B$504,A8,'Zgłoszenia'!$M$5:$M$504,Ustawienia!$J$6)>0,"W naprawie",IF(D8>0,"Usterka zgłoszona","Sprawny")))) | D8: =IF(A8="","",COUNTIFS('Zgłoszenia'!$B$5:$B$504,A8,'Zgłoszenia'!$O$5:$O$504,"TAK")) | E8: =IF(A8="","",IF(D8=0,"Brak otwartych usterek",IF(INDEX('Zgłoszenia'!$D$5:$D$504,G8)="","",RIGHT("0"&DAY(INDEX('Zgłoszenia'!$D$5:$D$504,G8)),2)&"."&RIGHT("0"&MONTH(INDEX('Zgłoszenia'!$D$5:$D$504,G8)),2)&"."&YEAR(INDEX('Zgłoszenia'!$D$5:$D$504,G8)))&" · "&INDEX('Zgłoszenia'!$H$5:$H$504,G8)&" — "&IF(INDEX('Zgłoszenia'!$M$5:$M$504,G8)="","Zgłoszona",INDEX('Zgłoszenia'!$M$5:$M$504,G8)))) | G8: =IF(OR(A8="",D8=0),"",MATCH(SUMPRODUCT(MAX(('Zgłoszenia'!$B$5:$B$504=A8)*'Zgłoszenia'!$R$5:$R$504)),'Zgłoszenia'!$R$5:$R$504,0))
A9: =IF('Wózki'!A3="","",'Wózki'!A3) | B9: =IF(A9="","",'Wózki'!B3&"") | C9: =IF(A9="","",IF(COUNTIFS('Zgłoszenia'!$B$5:$B$504,A9,'Zgłoszenia'!$O$5:$O$504,"TAK",'Zgłoszenia'!$L$5:$L$504,"TAK")>0,"Wyłączony z pracy",IF(COUNTIFS('Zgłoszenia'!$B$5:$B$504,A9,'Zgłoszenia'!$M$5:$M$504,Ustawienia!$J$5)+COUNTIFS('Zgłoszenia'!$B$5:$B$504,A9,'Zgłoszenia'!$M$5:$M$504,Ustawienia!$J$6)>0,"W naprawie",IF(D9>0,"Usterka zgłoszona","Sprawny")))) | D9: =IF(A9="","",COUNTIFS('Zgłoszenia'!$B$5:$B$504,A9,'Zgłoszenia'!$O$5:$O$504,"TAK")) | E9: =IF(A9="","",IF(D9=0,"Brak otwartych usterek",IF(INDEX('Zgłoszenia'!$D$5:$D$504,G9)="","",RIGHT("0"&DAY(INDEX('Zgłoszenia'!$D$5:$D$504,G9)),2)&"."&RIGHT("0"&MONTH(INDEX('Zgłoszenia'!$D$5:$D$504,G9)),2)&"."&YEAR(INDEX('Zgłoszenia'!$D$5:$D$504,G9)))&" · "&INDEX('Zgłoszenia'!$H$5:$H$504,G9)&" — "&IF(INDEX('Zgłoszenia'!$M$5:$M$504,G9)="","Zgłoszona",INDEX('Zgłoszenia'!$M$5:$M$504,G9)))) | G9: =IF(OR(A9="",D9=0),"",MATCH(SUMPRODUCT(MAX(('Zgłoszenia'!$B$5:$B$504=A9)*'Zgłoszenia'!$R$5:$R$504)),'Zgłoszenia'!$R$5:$R$504,0))
A10: =IF('Wózki'!A4="","",'Wózki'!A4) | B10: =IF(A10="","",'Wózki'!B4&"") | C10: =IF(A10="","",IF(COUNTIFS('Zgłoszenia'!$B$5:$B$504,A10,'Zgłoszenia'!$O$5:$O$504,"TAK",'Zgłoszenia'!$L$5:$L$504,"TAK")>0,"Wyłączony z pracy",IF(COUNTIFS('Zgłoszenia'!$B$5:$B$504,A10,'Zgłoszenia'!$M$5:$M$504,Ustawienia!$J$5)+COUNTIFS('Zgłoszenia'!$B$5:$B$504,A10,'Zgłoszenia'!$M$5:$M$504,Ustawienia!$J$6)>0,"W naprawie",IF(D10>0,"Usterka zgłoszona","Sprawny")))) | D10: =IF(A10="","",COUNTIFS('Zgłoszenia'!$B$5:$B$504,A10,'Zgłoszenia'!$O$5:$O$504,"TAK")) | E10: =IF(A10="","",IF(D10=0,"Brak otwartych usterek",IF(INDEX('Zgłoszenia'!$D$5:$D$504,G10)="","",RIGHT("0"&DAY(INDEX('Zgłoszenia'!$D$5:$D$504,G10)),2)&"."&RIGHT("0"&MONTH(INDEX('Zgłoszenia'!$D$5:$D$504,G10)),2)&"."&YEAR(INDEX('Zgłoszenia'!$D$5:$D$504,G10)))&" · "&INDEX('Zgłoszenia'!$H$5:$H$504,G10)&" — "&IF(INDEX('Zgłoszenia'!$M$5:$M$504,G10)="","Zgłoszona",INDEX('Zgłoszenia'!$M$5:$M$504,G10)))) | G10: =IF(OR(A10="",D10=0),"",MATCH(SUMPRODUCT(MAX(('Zgłoszenia'!$B$5:$B$504=A10)*'Zgłoszenia'!$R$5:$R$504)),'Zgłoszenia'!$R$5:$R$504,0))
A11: =IF('Wózki'!A5="","",'Wózki'!A5) | B11: =IF(A11="","",'Wózki'!B5&"") | C11: =IF(A11="","",IF(COUNTIFS('Zgłoszenia'!$B$5:$B$504,A11,'Zgłoszenia'!$O$5:$O$504,"TAK",'Zgłoszenia'!$L$5:$L$504,"TAK")>0,"Wyłączony z pracy",IF(COUNTIFS('Zgłoszenia'!$B$5:$B$504,A11,'Zgłoszenia'!$M$5:$M$504,Ustawienia!$J$5)+COUNTIFS('Zgłoszenia'!$B$5:$B$504,A11,'Zgłoszenia'!$M$5:$M$504,Ustawienia!$J$6)>0,"W naprawie",IF(D11>0,"Usterka zgłoszona","Sprawny")))) | D11: =IF(A11="","",COUNTIFS('Zgłoszenia'!$B$5:$B$504,A11,'Zgłoszenia'!$O$5:$O$504,"TAK")) | E11: =IF(A11="","",IF(D11=0,"Brak otwartych usterek",IF(INDEX('Zgłoszenia'!$D$5:$D$504,G11)="","",RIGHT("0"&DAY(INDEX('Zgłoszenia'!$D$5:$D$504,G11)),2)&"."&RIGHT("0"&MONTH(INDEX('Zgłoszenia'!$D$5:$D$504,G11)),2)&"."&YEAR(INDEX('Zgłoszenia'!$D$5:$D$504,G11)))&" · "&INDEX('Zgłoszenia'!$H$5:$H$504,G11)&" — "&IF(INDEX('Zgłoszenia'!$M$5:$M$504,G11)="","Zgłoszona",INDEX('Zgłoszenia'!$M$5:$M$504,G11)))) | G11: =IF(OR(A11="",D11=0),"",MATCH(SUMPRODUCT(MAX(('Zgłoszenia'!$B$5:$B$504=A11)*'Zgłoszenia'!$R$5:$R$504)),'Zgłoszenia'!$R$5:$R$504,0))
A12: =IF('Wózki'!A6="","",'Wózki'!A6) | B12: =IF(A12="","",'Wózki'!B6&"") | C12: =IF(A12="","",IF(COUNTIFS('Zgłoszenia'!$B$5:$B$504,A12,'Zgłoszenia'!$O$5:$O$504,"TAK",'Zgłoszenia'!$L$5:$L$504,"TAK")>0,"Wyłączony z pracy",IF(COUNTIFS('Zgłoszenia'!$B$5:$B$504,A12,'Zgłoszenia'!$M$5:$M$504,Ustawienia!$J$5)+COUNTIFS('Zgłoszenia'!$B$5:$B$504,A12,'Zgłoszenia'!$M$5:$M$504,Ustawienia!$J$6)>0,"W naprawie",IF(D12>0,"Usterka zgłoszona","Sprawny")))) | D12: =IF(A12="","",COUNTIFS('Zgłoszenia'!$B$5:$B$504,A12,'Zgłoszenia'!$O$5:$O$504,"TAK")) | E12: =IF(A12="","",IF(D12=0,"Brak otwartych usterek",IF(INDEX('Zgłoszenia'!$D$5:$D$504,G12)="","",RIGHT("0"&DAY(INDEX('Zgłoszenia'!$D$5:$D$504,G12)),2)&"."&RIGHT("0"&MONTH(INDEX('Zgłoszenia'!$D$5:$D$504,G12)),2)&"."&YEAR(INDEX('Zgłoszenia'!$D$5:$D$504,G12)))&" · "&INDEX('Zgłoszenia'!$H$5:$H$504,G12)&" — "&IF(INDEX('Zgłoszenia'!$M$5:$M$504,G12)="","Zgłoszona",INDEX('Zgłoszenia'!$M$5:$M$504,G12)))) | G12: =IF(OR(A12="",D12=0),"",MATCH(SUMPRODUCT(MAX(('Zgłoszenia'!$B$5:$B$504=A12)*'Zgłoszenia'!$R$5:$R$504)),'Zgłoszenia'!$R$5:$R$504,0))
A13: =IF('Wózki'!A7="","",'Wózki'!A7) | B13: =IF(A13="","",'Wózki'!B7&"") | C13: =IF(A13="","",IF(COUNTIFS('Zgłoszenia'!$B$5:$B$504,A13,'Zgłoszenia'!$O$5:$O$504,"TAK",'Zgłoszenia'!$L$5:$L$504,"TAK")>0,"Wyłączony z pracy",IF(COUNTIFS('Zgłoszenia'!$B$5:$B$504,A13,'Zgłoszenia'!$M$5:$M$504,Ustawienia!$J$5)+COUNTIFS('Zgłoszenia'!$B$5:$B$504,A13,'Zgłoszenia'!$M$5:$M$504,Ustawienia!$J$6)>0,"W naprawie",IF(D13>0,"Usterka zgłoszona","Sprawny")))) | D13: =IF(A13="","",COUNTIFS('Zgłoszenia'!$B$5:$B$504,A13,'Zgłoszenia'!$O$5:$O$504,"TAK")) | E13: =IF(A13="","",IF(D13=0,"Brak otwartych usterek",IF(INDEX('Zgłoszenia'!$D$5:$D$504,G13)="","",RIGHT("0"&DAY(INDEX('Zgłoszenia'!$D$5:$D$504,G13)),2)&"."&RIGHT("0"&MONTH(INDEX('Zgłoszenia'!$D$5:$D$504,G13)),2)&"."&YEAR(INDEX('Zgłoszenia'!$D$5:$D$504,G13)))&" · "&INDEX('Zgłoszenia'!$H$5:$H$504,G13)&" — "&IF(INDEX('Zgłoszenia'!$M$5:$M$504,G13)="","Zgłoszona",INDEX('Zgłoszenia'!$M$5:$M$504,G13)))) | G13: =IF(OR(A13="",D13=0),"",MATCH(SUMPRODUCT(MAX(('Zgłoszenia'!$B$5:$B$504=A13)*'Zgłoszenia'!$R$5:$R$504)),'Zgłoszenia'!$R$5:$R$504,0))
A14: =IF('Wózki'!A8="","",'Wózki'!A8) | B14: =IF(A14="","",'Wózki'!B8&"") | C14: =IF(A14="","",IF(COUNTIFS('Zgłoszenia'!$B$5:$B$504,A14,'Zgłoszenia'!$O$5:$O$504,"TAK",'Zgłoszenia'!$L$5:$L$504,"TAK")>0,"Wyłączony z pracy",IF(COUNTIFS('Zgłoszenia'!$B$5:$B$504,A14,'Zgłoszenia'!$M$5:$M$504,Ustawienia!$J$5)+COUNTIFS('Zgłoszenia'!$B$5:$B$504,A14,'Zgłoszenia'!$M$5:$M$504,Ustawienia!$J$6)>0,"W naprawie",IF(D14>0,"Usterka zgłoszona","Sprawny")))) | D14: =IF(A14="","",COUNTIFS('Zgłoszenia'!$B$5:$B$504,A14,'Zgłoszenia'!$O$5:$O$504,"TAK")) | E14: =IF(A14="","",IF(D14=0,"Brak otwartych usterek",IF(INDEX('Zgłoszenia'!$D$5:$D$504,G14)="","",RIGHT("0"&DAY(INDEX('Zgłoszenia'!$D$5:$D$504,G14)),2)&"."&RIGHT("0"&MONTH(INDEX('Zgłoszenia'!$D$5:$D$504,G14)),2)&"."&YEAR(INDEX('Zgłoszenia'!$D$5:$D$504,G14)))&" · "&INDEX('Zgłoszenia'!$H$5:$H$504,G14)&" — "&IF(INDEX('Zgłoszenia'!$M$5:$M$504,G14)="","Zgłoszona",INDEX('Zgłoszenia'!$M$5:$M$504,G14)))) | G14: =IF(OR(A14="",D14=0),"",MATCH(SUMPRODUCT(MAX(('Zgłoszenia'!$B$5:$B$504=A14)*'Zgłoszenia'!$R$5:$R$504)),'Zgłoszenia'!$R$5:$R$504,0))
A15: =IF('Wózki'!A9="","",'Wózki'!A9) | B15: =IF(A15="","",'Wózki'!B9&"") | C15: =IF(A15="","",IF(COUNTIFS('Zgłoszenia'!$B$5:$B$504,A15,'Zgłoszenia'!$O$5:$O$504,"TAK",'Zgłoszenia'!$L$5:$L$504,"TAK")>0,"Wyłączony z pracy",IF(COUNTIFS('Zgłoszenia'!$B$5:$B$504,A15,'Zgłoszenia'!$M$5:$M$504,Ustawienia!$J$5)+COUNTIFS('Zgłoszenia'!$B$5:$B$504,A15,'Zgłoszenia'!$M$5:$M$504,Ustawienia!$J$6)>0,"W naprawie",IF(D15>0,"Usterka zgłoszona","Sprawny")))) | D15: =IF(A15="","",COUNTIFS('Zgłoszenia'!$B$5:$B$504,A15,'Zgłoszenia'!$O$5:$O$504,"TAK")) | E15: =IF(A15="","",IF(D15=0,"Brak otwartych usterek",IF(INDEX('Zgłoszenia'!$D$5:$D$504,G15)="","",RIGHT("0"&DAY(INDEX('Zgłoszenia'!$D$5:$D$504,G15)),2)&"."&RIGHT("0"&MONTH(INDEX('Zgłoszenia'!$D$5:$D$504,G15)),2)&"."&YEAR(INDEX('Zgłoszenia'!$D$5:$D$504,G15)))&" · "&INDEX('Zgłoszenia'!$H$5:$H$504,G15)&" — "&IF(INDEX('Zgłoszenia'!$M$5:$M$504,G15)="","Zgłoszona",INDEX('Zgłoszenia'!$M$5:$M$504,G15)))) | G15: =IF(OR(A15="",D15=0),"",MATCH(SUMPRODUCT(MAX(('Zgłoszenia'!$B$5:$B$504=A15)*'Zgłoszenia'!$R$5:$R$504)),'Zgłoszenia'!$R$5:$R$504,0))
A16: =IF('Wózki'!A10="","",'Wózki'!A10) | B16: =IF(A16="","",'Wózki'!B10&"") | C16: =IF(A16="","",IF(COUNTIFS('Zgłoszenia'!$B$5:$B$504,A16,'Zgłoszenia'!$O$5:$O$504,"TAK",'Zgłoszenia'!$L$5:$L$504,"TAK")>0,"Wyłączony z pracy",IF(COUNTIFS('Zgłoszenia'!$B$5:$B$504,A16,'Zgłoszenia'!$M$5:$M$504,Ustawienia!$J$5)+COUNTIFS('Zgłoszenia'!$B$5:$B$504,A16,'Zgłoszenia'!$M$5:$M$504,Ustawienia!$J$6)>0,"W naprawie",IF(D16>0,"Usterka zgłoszona","Sprawny")))) | D16: =IF(A16="","",COUNTIFS('Zgłoszenia'!$B$5:$B$504,A16,'Zgłoszenia'!$O$5:$O$504,"TAK")) | E16: =IF(A16="","",IF(D16=0,"Brak otwartych usterek",IF(INDEX('Zgłoszenia'!$D$5:$D$504,G16)="","",RIGHT("0"&DAY(INDEX('Zgłoszenia'!$D$5:$D$504,G16)),2)&"."&RIGHT("0"&MONTH(INDEX('Zgłoszenia'!$D$5:$D$504,G16)),2)&"."&YEAR(INDEX('Zgłoszenia'!$D$5:$D$504,G16)))&" · "&INDEX('Zgłoszenia'!$H$5:$H$504,G16)&" — "&IF(INDEX('Zgłoszenia'!$M$5:$M$504,G16)="","Zgłoszona",INDEX('Zgłoszenia'!$M$5:$M$504,G16)))) | G16: =IF(OR(A16="",D16=0),"",MATCH(SUMPRODUCT(MAX(('Zgłoszenia'!$B$5:$B$504=A16)*'Zgłoszenia'!$R$5:$R$504)),'Zgłoszenia'!$R$5:$R$504,0))
A17: =IF('Wózki'!A11="","",'Wózki'!A11) | B17: =IF(A17="","",'Wózki'!B11&"") | C17: =IF(A17="","",IF(COUNTIFS('Zgłoszenia'!$B$5:$B$504,A17,'Zgłoszenia'!$O$5:$O$504,"TAK",'Zgłoszenia'!$L$5:$L$504,"TAK")>0,"Wyłączony z pracy",IF(COUNTIFS('Zgłoszenia'!$B$5:$B$504,A17,'Zgłoszenia'!$M$5:$M$504,Ustawienia!$J$5)+COUNTIFS('Zgłoszenia'!$B$5:$B$504,A17,'Zgłoszenia'!$M$5:$M$504,Ustawienia!$J$6)>0,"W naprawie",IF(D17>0,"Usterka zgłoszona","Sprawny")))) | D17: =IF(A17="","",COUNTIFS('Zgłoszenia'!$B$5:$B$504,A17,'Zgłoszenia'!$O$5:$O$504,"TAK")) | E17: =IF(A17="","",IF(D17=0,"Brak otwartych usterek",IF(INDEX('Zgłoszenia'!$D$5:$D$504,G17)="","",RIGHT("0"&DAY(INDEX('Zgłoszenia'!$D$5:$D$504,G17)),2)&"."&RIGHT("0"&MONTH(INDEX('Zgłoszenia'!$D$5:$D$504,G17)),2)&"."&YEAR(INDEX('Zgłoszenia'!$D$5:$D$504,G17)))&" · "&INDEX('Zgłoszenia'!$H$5:$H$504,G17)&" — "&IF(INDEX('Zgłoszenia'!$M$5:$M$504,G17)="","Zgłoszona",INDEX('Zgłoszenia'!$M$5:$M$504,G17)))) | G17: =IF(OR(A17="",D17=0),"",MATCH(SUMPRODUCT(MAX(('Zgłoszenia'!$B$5:$B$504=A17)*'Zgłoszenia'!$R$5:$R$504)),'Zgłoszenia'!$R$5:$R$504,0))
A18: =IF('Wózki'!A12="","",'Wózki'!A12) | B18: =IF(A18="","",'Wózki'!B12&"") | C18: =IF(A18="","",IF(COUNTIFS('Zgłoszenia'!$B$5:$B$504,A18,'Zgłoszenia'!$O$5:$O$504,"TAK",'Zgłoszenia'!$L$5:$L$504,"TAK")>0,"Wyłączony z pracy",IF(COUNTIFS('Zgłoszenia'!$B$5:$B$504,A18,'Zgłoszenia'!$M$5:$M$504,Ustawienia!$J$5)+COUNTIFS('Zgłoszenia'!$B$5:$B$504,A18,'Zgłoszenia'!$M$5:$M$504,Ustawienia!$J$6)>0,"W naprawie",IF(D18>0,"Usterka zgłoszona","Sprawny")))) | D18: =IF(A18="","",COUNTIFS('Zgłoszenia'!$B$5:$B$504,A18,'Zgłoszenia'!$O$5:$O$504,"TAK")) | E18: =IF(A18="","",IF(D18=0,"Brak otwartych usterek",IF(INDEX('Zgłoszenia'!$D$5:$D$504,G18)="","",RIGHT("0"&DAY(INDEX('Zgłoszenia'!$D$5:$D$504,G18)),2)&"."&RIGHT("0"&MONTH(INDEX('Zgłoszenia'!$D$5:$D$504,G18)),2)&"."&YEAR(INDEX('Zgłoszenia'!$D$5:$D$504,G18)))&" · "&INDEX('Zgłoszenia'!$H$5:$H$504,G18)&" — "&IF(INDEX('Zgłoszenia'!$M$5:$M$504,G18)="","Zgłoszona",INDEX('Zgłoszenia'!$M$5:$M$504,G18)))) | G18: =IF(OR(A18="",D18=0),"",MATCH(SUMPRODUCT(MAX(('Zgłoszenia'!$B$5:$B$504=A18)*'Zgłoszenia'!$R$5:$R$504)),'Zgłoszenia'!$R$5:$R$504,0))
A19: =IF('Wózki'!A13="","",'Wózki'!A13) | B19: =IF(A19="","",'Wózki'!B13&"") | C19: =IF(A19="","",IF(COUNTIFS('Zgłoszenia'!$B$5:$B$504,A19,'Zgłoszenia'!$O$5:$O$504,"TAK",'Zgłoszenia'!$L$5:$L$504,"TAK")>0,"Wyłączony z pracy",IF(COUNTIFS('Zgłoszenia'!$B$5:$B$504,A19,'Zgłoszenia'!$M$5:$M$504,Ustawienia!$J$5)+COUNTIFS('Zgłoszenia'!$B$5:$B$504,A19,'Zgłoszenia'!$M$5:$M$504,Ustawienia!$J$6)>0,"W naprawie",IF(D19>0,"Usterka zgłoszona","Sprawny")))) | D19: =IF(A19="","",COUNTIFS('Zgłoszenia'!$B$5:$B$504,A19,'Zgłoszenia'!$O$5:$O$504,"TAK")) | E19: =IF(A19="","",IF(D19=0,"Brak otwartych usterek",IF(INDEX('Zgłoszenia'!$D$5:$D$504,G19)="","",RIGHT("0"&DAY(INDEX('Zgłoszenia'!$D$5:$D$504,G19)),2)&"."&RIGHT("0"&MONTH(INDEX('Zgłoszenia'!$D$5:$D$504,G19)),2)&"."&YEAR(INDEX('Zgłoszenia'!$D$5:$D$504,G19)))&" · "&INDEX('Zgłoszenia'!$H$5:$H$504,G19)&" — "&IF(INDEX('Zgłoszenia'!$M$5:$M$504,G19)="","Zgłoszona",INDEX('Zgłoszenia'!$M$5:$M$504,G19)))) | G19: =IF(OR(A19="",D19=0),"",MATCH(SUMPRODUCT(MAX(('Zgłoszenia'!$B$5:$B$504=A19)*'Zgłoszenia'!$R$5:$R$504)),'Zgłoszenia'!$R$5:$R$504,0))
... A207: =IF('Wózki'!A201="","",'Wózki'!A201) | B207: =IF(A207="","",'Wózki'!B201&"") | C207: =IF(A207="","",IF(COUNTIFS('Zgłoszenia'!$B$5:$B$504,A207,'Zgłoszenia'!$O$5:$O$504,"TAK",'Zgłoszenia'!$L$5:$L$504,"TAK")>0,"Wyłączony z pracy",IF(COUNTIFS('Zgłoszenia'!$B$5:$B$504,A207,'Zgłoszenia'!$M$5:$M$504,Ustawienia!$J$5)+COUNTIFS('Zgłoszenia'!$B$5:$B$504,A207,'Zgłoszenia'!$M$5:$M$504,Ustawienia!$J$6)>0,"W naprawie",IF(D207>0,"Usterka zgłoszona","Sprawny")))) | D207: =IF(A207="","",COUNTIFS('Zgłoszenia'!$B$5:$B$504,A207,'Zgłoszenia'!$O$5:$O$504,"TAK")) | E207: =IF(A207="","",IF(D207=0,"Brak otwartych usterek",IF(INDEX('Zgłoszenia'!$D$5:$D$504,G207)="","",RIGHT("0"&DAY(INDEX('Zgłoszenia'!$D$5:$D$504,G207)),2)&"."&RIGHT("0"&MONTH(INDEX('Zgłoszenia'!$D$5:$D$504,G207)),2)&"."&YEAR(INDEX('Zgłoszenia'!$D$5:$D$504,G207)))&" · "&INDEX('Zgłoszenia'!$H$5:$H$504,G207)&" — "&IF(INDEX('Zgłoszenia'!$M$5:$M$504,G207)="","Zgłoszona",INDEX('Zgłoszenia'!$M$5:$M$504,G207)))) | G207: =IF(OR(A207="",D207=0),"",MATCH(SUMPRODUCT(MAX(('Zgłoszenia'!$B$5:$B$504=A207)*'Zgłoszenia'!$R$5:$R$504)),'Zgłoszenia'!$R$5:$R$504,0))

Sheet Zgłoszenia
A1: ZGŁOSZENIA USZKODZEŃ
A2: ="Otwarte (do naprawy): "&COUNTIF('Zgłoszenia'!$O$5:$O$504,"TAK")&" · wszystkich: "&COUNTA('Zgłoszenia'!$B$5:$B$504) | H2: Żółte kolumny wypełniasz, białe liczą się same. Filtry w nagłówku = filtry z aplikacji. | S2: =MAX(5,SUMPRODUCT(MAX((B5:B504<>"")*ROW(B5:B504))))
A4: Lp | B4: Wózek | C4: Typ wózka | D4: Data zdarzenia | E4: Zmiana | F4: Pracownik (operator) | G4: Dział | H4: Rodzaj uderzenia | I4: Co uszkodzone | J4: Kiedy powstało | K4: Opis zdarzenia | L4: Wyłączony z pracy | M4: Status | N4: Notatka / naprawa | O4: Otwarte? | P4: Wg rozpiski | Q4: klucz historii | R4: klucz otwartych | S4: klucz wózek|data
A5: =IF(B5="","",ROW()-4) | B5: 105 | C5: =IF(B5="","",IFERROR(INDEX('Wózki'!$B$2:$B$500,MATCH(B5,'Wózki'!$A$2:$A$500,0))&"","")) | D5: 46296 | E5: I | F5: KOWALSKI JAN | G5: =IF(F5="","",IFERROR(INDEX(Pracownicy!$B$2:$B$2000,MATCH(F5,Pracownicy!$A$2:$A$2000,0))&"","")) | H5: Uderzenie w regał | I5: Widły / platforma | J5: Zgłoszone przez sprawcę | K5: Przykład: przy odkładaniu palety w alejce C uderzył widłami w słup regału C4; wygięty lewy ząb wideł. | L5: TAK | M5: Zgłoszona | O5: =IF(B5="","",IF(M5="","TAK",IFERROR(INDEX(Ustawienia!$K$4:$K$8,MATCH(M5,Ustawienia!$J$4:$J$8,0)),"TAK"))) | P5: =IF(OR(B5="",D5=""),"",IFERROR(INDEX('Dane rozpisek'!$B$2:$B$2600,MATCH(S5,'Dane rozpisek'!$H$2:$H$2600,0))&": "&INDEX('Dane rozpisek'!$E$2:$E$2600,MATCH(S5,'Dane rozpisek'!$H$2:$H$2600,0))&IF(COUNTIF('Dane rozpisek'!$H$2:$H$2600,S5)>1," (+"&(COUNTIF('Dane rozpisek'!$H$2:$H$2600,S5)-1)&")",""),"—")) | Q5: =IF(AND(B5<>"",D5<>"",OR('Historia wózka'!$B$4="",B5='Historia wózka'!$B$4),D5>='Historia wózka'!$B$5,D5<='Historia wózka'!$B$6),D5+ROW()/1000000,0) | R5: =IF(O5="TAK",IF(D5="",0,D5)+ROW()/1000000,0) | S5: =IF(OR(B5="",D5=""),"",B5&"|"&D5)
A6: =IF(B6="","",ROW()-4) | C6: =IF(B6="","",IFERROR(INDEX('Wózki'!$B$2:$B$500,MATCH(B6,'Wózki'!$A$2:$A$500,0))&"","")) | G6: =IF(F6="","",IFERROR(INDEX(Pracownicy!$B$2:$B$2000,MATCH(F6,Pracownicy!$A$2:$A$2000,0))&"","")) | O6: =IF(B6="","",IF(M6="","TAK",IFERROR(INDEX(Ustawienia!$K$4:$K$8,MATCH(M6,Ustawienia!$J$4:$J$8,0)),"TAK"))) | P6: =IF(OR(B6="",D6=""),"",IFERROR(INDEX('Dane rozpisek'!$B$2:$B$2600,MATCH(S6,'Dane rozpisek'!$H$2:$H$2600,0))&": "&INDEX('Dane rozpisek'!$E$2:$E$2600,MATCH(S6,'Dane rozpisek'!$H$2:$H$2600,0))&IF(COUNTIF('Dane rozpisek'!$H$2:$H$2600,S6)>1," (+"&(COUNTIF('Dane rozpisek'!$H$2:$H$2600,S6)-1)&")",""),"—")) | Q6: =IF(AND(B6<>"",D6<>"",OR('Historia wózka'!$B$4="",B6='Historia wózka'!$B$4),D6>='Historia wózka'!$B$5,D6<='Historia wózka'!$B$6),D6+ROW()/1000000,0) | R6: =IF(O6="TAK",IF(D6="",0,D6)+ROW()/1000000,0) | S6: =IF(OR(B6="",D6=""),"",B6&"|"&D6)
A7: =IF(B7="","",ROW()-4) | C7: =IF(B7="","",IFERROR(INDEX('Wózki'!$B$2:$B$500,MATCH(B7,'Wózki'!$A$2:$A$500,0))&"","")) | G7: =IF(F7="","",IFERROR(INDEX(Pracownicy!$B$2:$B$2000,MATCH(F7,Pracownicy!$A$2:$A$2000,0))&"","")) | O7: =IF(B7="","",IF(M7="","TAK",IFERROR(INDEX(Ustawienia!$K$4:$K$8,MATCH(M7,Ustawienia!$J$4:$J$8,0)),"TAK"))) | P7: =IF(OR(B7="",D7=""),"",IFERROR(INDEX('Dane rozpisek'!$B$2:$B$2600,MATCH(S7,'Dane rozpisek'!$H$2:$H$2600,0))&": "&INDEX('Dane rozpisek'!$E$2:$E$2600,MATCH(S7,'Dane rozpisek'!$H$2:$H$2600,0))&IF(COUNTIF('Dane rozpisek'!$H$2:$H$2600,S7)>1," (+"&(COUNTIF('Dane rozpisek'!$H$2:$H$2600,S7)-1)&")",""),"—")) | Q7: =IF(AND(B7<>"",D7<>"",OR('Historia wózka'!$B$4="",B7='Historia wózka'!$B$4),D7>='Historia wózka'!$B$5,D7<='Historia wózka'!$B$6),D7+ROW()/1000000,0) | R7: =IF(O7="TAK",IF(D7="",0,D7)+ROW()/1000000,0) | S7: =IF(OR(B7="",D7=""),"",B7&"|"&D7)
A8: =IF(B8="","",ROW()-4) | C8: =IF(B8="","",IFERROR(INDEX('Wózki'!$B$2:$B$500,MATCH(B8,'Wózki'!$A$2:$A$500,0))&"","")) | G8: =IF(F8="","",IFERROR(INDEX(Pracownicy!$B$2:$B$2000,MATCH(F8,Pracownicy!$A$2:$A$2000,0))&"","")) | O8: =IF(B8="","",IF(M8="","TAK",IFERROR(INDEX(Ustawienia!$K$4:$K$8,MATCH(M8,Ustawienia!$J$4:$J$8,0)),"TAK"))) | P8: =IF(OR(B8="",D8=""),"",IFERROR(INDEX('Dane rozpisek'!$B$2:$B$2600,MATCH(S8,'Dane rozpisek'!$H$2:$H$2600,0))&": "&INDEX('Dane rozpisek'!$E$2:$E$2600,MATCH(S8,'Dane rozpisek'!$H$2:$H$2600,0))&IF(COUNTIF('Dane rozpisek'!$H$2:$H$2600,S8)>1," (+"&(COUNTIF('Dane rozpisek'!$H$2:$H$2600,S8)-1)&")",""),"—")) | Q8: =IF(AND(B8<>"",D8<>"",OR('Historia wózka'!$B$4="",B8='Historia wózka'!$B$4),D8>='Historia wózka'!$B$5,D8<='Historia wózka'!$B$6),D8+ROW()/1000000,0) | R8: =IF(O8="TAK",IF(D8="",0,D8)+ROW()/1000000,0) | S8: =IF(OR(B8="",D8=""),"",B8&"|"&D8)
A9: =IF(B9="","",ROW()-4) | C9: =IF(B9="","",IFERROR(INDEX('Wózki'!$B$2:$B$500,MATCH(B9,'Wózki'!$A$2:$A$500,0))&"","")) | G9: =IF(F9="","",IFERROR(INDEX(Pracownicy!$B$2:$B$2000,MATCH(F9,Pracownicy!$A$2:$A$2000,0))&"","")) | O9: =IF(B9="","",IF(M9="","TAK",IFERROR(INDEX(Ustawienia!$K$4:$K$8,MATCH(M9,Ustawienia!$J$4:$J$8,0)),"TAK"))) | P9: =IF(OR(B9="",D9=""),"",IFERROR(INDEX('Dane rozpisek'!$B$2:$B$2600,MATCH(S9,'Dane rozpisek'!$H$2:$H$2600,0))&": "&INDEX('Dane rozpisek'!$E$2:$E$2600,MATCH(S9,'Dane rozpisek'!$H$2:$H$2600,0))&IF(COUNTIF('Dane rozpisek'!$H$2:$H$2600,S9)>1," (+"&(COUNTIF('Dane rozpisek'!$H$2:$H$2600,S9)-1)&")",""),"—")) | Q9: =IF(AND(B9<>"",D9<>"",OR('Historia wózka'!$B$4="",B9='Historia wózka'!$B$4),D9>='Historia wózka'!$B$5,D9<='Historia wózka'!$B$6),D9+ROW()/1000000,0) | R9: =IF(O9="TAK",IF(D9="",0,D9)+ROW()/1000000,0) | S9: =IF(OR(B9="",D9=""),"",B9&"|"&D9)
A10: =IF(B10="","",ROW()-4) | C10: =IF(B10="","",IFERROR(INDEX('Wózki'!$B$2:$B$500,MATCH(B10,'Wózki'!$A$2:$A$500,0))&"","")) | G10: =IF(F10="","",IFERROR(INDEX(Pracownicy!$B$2:$B$2000,MATCH(F10,Pracownicy!$A$2:$A$2000,0))&"","")) | O10: =IF(B10="","",IF(M10="","TAK",IFERROR(INDEX(Ustawienia!$K$4:$K$8,MATCH(M10,Ustawienia!$J$4:$J$8,0)),"TAK"))) | P10: =IF(OR(B10="",D10=""),"",IFERROR(INDEX('Dane rozpisek'!$B$2:$B$2600,MATCH(S10,'Dane rozpisek'!$H$2:$H$2600,0))&": "&INDEX('Dane rozpisek'!$E$2:$E$2600,MATCH(S10,'Dane rozpisek'!$H$2:$H$2600,0))&IF(COUNTIF('Dane rozpisek'!$H$2:$H$2600,S10)>1," (+"&(COUNTIF('Dane rozpisek'!$H$2:$H$2600,S10)-1)&")",""),"—")) | Q10: =IF(AND(B10<>"",D10<>"",OR('Historia wózka'!$B$4="",B10='Historia wózka'!$B$4),D10>='Historia wózka'!$B$5,D10<='Historia wózka'!$B$6),D10+ROW()/1000000,0) | R10: =IF(O10="TAK",IF(D10="",0,D10)+ROW()/1000000,0) | S10: =IF(OR(B10="",D10=""),"",B10&"|"&D10)
A11: =IF(B11="","",ROW()-4) | C11: =IF(B11="","",IFERROR(INDEX('Wózki'!$B$2:$B$500,MATCH(B11,'Wózki'!$A$2:$A$500,0))&"","")) | G11: =IF(F11="","",IFERROR(INDEX(Pracownicy!$B$2:$B$2000,MATCH(F11,Pracownicy!$A$2:$A$2000,0))&"","")) | O11: =IF(B11="","",IF(M11="","TAK",IFERROR(INDEX(Ustawienia!$K$4:$K$8,MATCH(M11,Ustawienia!$J$4:$J$8,0)),"TAK"))) | P11: =IF(OR(B11="",D11=""),"",IFERROR(INDEX('Dane rozpisek'!$B$2:$B$2600,MATCH(S11,'Dane rozpisek'!$H$2:$H$2600,0))&": "&INDEX('Dane rozpisek'!$E$2:$E$2600,MATCH(S11,'Dane rozpisek'!$H$2:$H$2600,0))&IF(COUNTIF('Dane rozpisek'!$H$2:$H$2600,S11)>1," (+"&(COUNTIF('Dane rozpisek'!$H$2:$H$2600,S11)-1)&")",""),"—")) | Q11: =IF(AND(B11<>"",D11<>"",OR('Historia wózka'!$B$4="",B11='Historia wózka'!$B$4),D11>='Historia wózka'!$B$5,D11<='Historia wózka'!$B$6),D11+ROW()/1000000,0) | R11: =IF(O11="TAK",IF(D11="",0,D11)+ROW()/1000000,0) | S11: =IF(OR(B11="",D11=""),"",B11&"|"&D11)
A12: =IF(B12="","",ROW()-4) | C12: =IF(B12="","",IFERROR(INDEX('Wózki'!$B$2:$B$500,MATCH(B12,'Wózki'!$A$2:$A$500,0))&"","")) | G12: =IF(F12="","",IFERROR(INDEX(Pracownicy!$B$2:$B$2000,MATCH(F12,Pracownicy!$A$2:$A$2000,0))&"","")) | O12: =IF(B12="","",IF(M12="","TAK",IFERROR(INDEX(Ustawienia!$K$4:$K$8,MATCH(M12,Ustawienia!$J$4:$J$8,0)),"TAK"))) | P12: =IF(OR(B12="",D12=""),"",IFERROR(INDEX('Dane rozpisek'!$B$2:$B$2600,MATCH(S12,'Dane rozpisek'!$H$2:$H$2600,0))&": "&INDEX('Dane rozpisek'!$E$2:$E$2600,MATCH(S12,'Dane rozpisek'!$H$2:$H$2600,0))&IF(COUNTIF('Dane rozpisek'!$H$2:$H$2600,S12)>1," (+"&(COUNTIF('Dane rozpisek'!$H$2:$H$2600,S12)-1)&")",""),"—")) | Q12: =IF(AND(B12<>"",D12<>"",OR('Historia wózka'!$B$4="",B12='Historia wózka'!$B$4),D12>='Historia wózka'!$B$5,D12<='Historia wózka'!$B$6),D12+ROW()/1000000,0) | R12: =IF(O12="TAK",IF(D12="",0,D12)+ROW()/1000000,0) | S12: =IF(OR(B12="",D12=""),"",B12&"|"&D12)
A13: =IF(B13="","",ROW()-4) | C13: =IF(B13="","",IFERROR(INDEX('Wózki'!$B$2:$B$500,MATCH(B13,'Wózki'!$A$2:$A$500,0))&"","")) | G13: =IF(F13="","",IFERROR(INDEX(Pracownicy!$B$2:$B$2000,MATCH(F13,Pracownicy!$A$2:$A$2000,0))&"","")) | O13: =IF(B13="","",IF(M13="","TAK",IFERROR(INDEX(Ustawienia!$K$4:$K$8,MATCH(M13,Ustawienia!$J$4:$J$8,0)),"TAK"))) | P13: =IF(OR(B13="",D13=""),"",IFERROR(INDEX('Dane rozpisek'!$B$2:$B$2600,MATCH(S13,'Dane rozpisek'!$H$2:$H$2600,0))&": "&INDEX('Dane rozpisek'!$E$2:$E$2600,MATCH(S13,'Dane rozpisek'!$H$2:$H$2600,0))&IF(COUNTIF('Dane rozpisek'!$H$2:$H$2600,S13)>1," (+"&(COUNTIF('Dane rozpisek'!$H$2:$H$2600,S13)-1)&")",""),"—")) | Q13: =IF(AND(B13<>"",D13<>"",OR('Historia wózka'!$B$4="",B13='Historia wózka'!$B$4),D13>='Historia wózka'!$B$5,D13<='Historia wózka'!$B$6),D13+ROW()/1000000,0) | R13: =IF(O13="TAK",IF(D13="",0,D13)+ROW()/1000000,0) | S13: =IF(OR(B13="",D13=""),"",B13&"|"&D13)
A14: =IF(B14="","",ROW()-4) | C14: =IF(B14="","",IFERROR(INDEX('Wózki'!$B$2:$B$500,MATCH(B14,'Wózki'!$A$2:$A$500,0))&"","")) | G14: =IF(F14="","",IFERROR(INDEX(Pracownicy!$B$2:$B$2000,MATCH(F14,Pracownicy!$A$2:$A$2000,0))&"","")) | O14: =IF(B14="","",IF(M14="","TAK",IFERROR(INDEX(Ustawienia!$K$4:$K$8,MATCH(M14,Ustawienia!$J$4:$J$8,0)),"TAK"))) | P14: =IF(OR(B14="",D14=""),"",IFERROR(INDEX('Dane rozpisek'!$B$2:$B$2600,MATCH(S14,'Dane rozpisek'!$H$2:$H$2600,0))&": "&INDEX('Dane rozpisek'!$E$2:$E$2600,MATCH(S14,'Dane rozpisek'!$H$2:$H$2600,0))&IF(COUNTIF('Dane rozpisek'!$H$2:$H$2600,S14)>1," (+"&(COUNTIF('Dane rozpisek'!$H$2:$H$2600,S14)-1)&")",""),"—")) | Q14: =IF(AND(B14<>"",D14<>"",OR('Historia wózka'!$B$4="",B14='Historia wózka'!$B$4),D14>='Historia wózka'!$B$5,D14<='Historia wózka'!$B$6),D14+ROW()/1000000,0) | R14: =IF(O14="TAK",IF(D14="",0,D14)+ROW()/1000000,0) | S14: =IF(OR(B14="",D14=""),"",B14&"|"&D14)
A15: =IF(B15="","",ROW()-4) | C15: =IF(B15="","",IFERROR(INDEX('Wózki'!$B$2:$B$500,MATCH(B15,'Wózki'!$A$2:$A$500,0))&"","")) | G15: =IF(F15="","",IFERROR(INDEX(Pracownicy!$B$2:$B$2000,MATCH(F15,Pracownicy!$A$2:$A$2000,0))&"","")) | O15: =IF(B15="","",IF(M15="","TAK",IFERROR(INDEX(Ustawienia!$K$4:$K$8,MATCH(M15,Ustawienia!$J$4:$J$8,0)),"TAK"))) | P15: =IF(OR(B15="",D15=""),"",IFERROR(INDEX('Dane rozpisek'!$B$2:$B$2600,MATCH(S15,'Dane rozpisek'!$H$2:$H$2600,0))&": "&INDEX('Dane rozpisek'!$E$2:$E$2600,MATCH(S15,'Dane rozpisek'!$H$2:$H$2600,0))&IF(COUNTIF('Dane rozpisek'!$H$2:$H$2600,S15)>1," (+"&(COUNTIF('Dane rozpisek'!$H$2:$H$2600,S15)-1)&")",""),"—")) | Q15: =IF(AND(B15<>"",D15<>"",OR('Historia wózka'!$B$4="",B15='Historia wózka'!$B$4),D15>='Historia wózka'!$B$5,D15<='Historia wózka'!$B$6),D15+ROW()/1000000,0) | R15: =IF(O15="TAK",IF(D15="",0,D15)+ROW()/1000000,0) | S15: =IF(OR(B15="",D15=""),"",B15&"|"&D15)
A16: =IF(B16="","",ROW()-4) | C16: =IF(B16="","",IFERROR(INDEX('Wózki'!$B$2:$B$500,MATCH(B16,'Wózki'!$A$2:$A$500,0))&"","")) | G16: =IF(F16="","",IFERROR(INDEX(Pracownicy!$B$2:$B$2000,MATCH(F16,Pracownicy!$A$2:$A$2000,0))&"","")) | O16: =IF(B16="","",IF(M16="","TAK",IFERROR(INDEX(Ustawienia!$K$4:$K$8,MATCH(M16,Ustawienia!$J$4:$J$8,0)),"TAK"))) | P16: =IF(OR(B16="",D16=""),"",IFERROR(INDEX('Dane rozpisek'!$B$2:$B$2600,MATCH(S16,'Dane rozpisek'!$H$2:$H$2600,0))&": "&INDEX('Dane rozpisek'!$E$2:$E$2600,MATCH(S16,'Dane rozpisek'!$H$2:$H$2600,0))&IF(COUNTIF('Dane rozpisek'!$H$2:$H$2600,S16)>1," (+"&(COUNTIF('Dane rozpisek'!$H$2:$H$2600,S16)-1)&")",""),"—")) | Q16: =IF(AND(B16<>"",D16<>"",OR('Historia wózka'!$B$4="",B16='Historia wózka'!$B$4),D16>='Historia wózka'!$B$5,D16<='Historia wózka'!$B$6),D16+ROW()/1000000,0) | R16: =IF(O16="TAK",IF(D16="",0,D16)+ROW()/1000000,0) | S16: =IF(OR(B16="",D16=""),"",B16&"|"&D16)
A17: =IF(B17="","",ROW()-4) | C17: =IF(B17="","",IFERROR(INDEX('Wózki'!$B$2:$B$500,MATCH(B17,'Wózki'!$A$2:$A$500,0))&"","")) | G17: =IF(F17="","",IFERROR(INDEX(Pracownicy!$B$2:$B$2000,MATCH(F17,Pracownicy!$A$2:$A$2000,0))&"","")) | O17: =IF(B17="","",IF(M17="","TAK",IFERROR(INDEX(Ustawienia!$K$4:$K$8,MATCH(M17,Ustawienia!$J$4:$J$8,0)),"TAK"))) | P17: =IF(OR(B17="",D17=""),"",IFERROR(INDEX('Dane rozpisek'!$B$2:$B$2600,MATCH(S17,'Dane rozpisek'!$H$2:$H$2600,0))&": "&INDEX('Dane rozpisek'!$E$2:$E$2600,MATCH(S17,'Dane rozpisek'!$H$2:$H$2600,0))&IF(COUNTIF('Dane rozpisek'!$H$2:$H$2600,S17)>1," (+"&(COUNTIF('Dane rozpisek'!$H$2:$H$2600,S17)-1)&")",""),"—")) | Q17: =IF(AND(B17<>"",D17<>"",OR('Historia wózka'!$B$4="",B17='Historia wózka'!$B$4),D17>='Historia wózka'!$B$5,D17<='Historia wózka'!$B$6),D17+ROW()/1000000,0) | R17: =IF(O17="TAK",IF(D17="",0,D17)+ROW()/1000000,0) | S17: =IF(OR(B17="",D17=""),"",B17&"|"&D17)
... A504: =IF(B504="","",ROW()-4) | C504: =IF(B504="","",IFERROR(INDEX('Wózki'!$B$2:$B$500,MATCH(B504,'Wózki'!$A$2:$A$500,0))&"","")) | G504: =IF(F504="","",IFERROR(INDEX(Pracownicy!$B$2:$B$2000,MATCH(F504,Pracownicy!$A$2:$A$2000,0))&"","")) | O504: =IF(B504="","",IF(M504="","TAK",IFERROR(INDEX(Ustawienia!$K$4:$K$8,MATCH(M504,Ustawienia!$J$4:$J$8,0)),"TAK"))) | P504: =IF(OR(B504="",D504=""),"",IFERROR(INDEX('Dane rozpisek'!$B$2:$B$2600,MATCH(S504,'Dane rozpisek'!$H$2:$H$2600,0))&": "&INDEX('Dane rozpisek'!$E$2:$E$2600,MATCH(S504,'Dane rozpisek'!$H$2:$H$2600,0))&IF(COUNTIF('Dane rozpisek'!$H$2:$H$2600,S504)>1," (+"&(COUNTIF('Dane rozpisek'!$H$2:$H$2600,S504)-1)&")",""),"—")) | Q504: =IF(AND(B504<>"",D504<>"",OR('Historia wózka'!$B$4="",B504='Historia wózka'!$B$4),D504>='Historia wózka'!$B$5,D504<='Historia wózka'!$B$6),D504+ROW()/1000000,0) | R504: =IF(O504="TAK",IF(D504="",0,D504)+ROW()/1000000,0) | S504: =IF(OR(B504="",D504=""),"",B504&"|"&D504)

Sheet Historia wózka
A1: HISTORIA WÓZKA
A2: =IF(B4="","Wszystkie wózki","Wózek "&B4)&" · "&IF(B5="","",RIGHT("0"&DAY(B5),2)&"."&RIGHT("0"&MONTH(B5),2)&"."&YEAR(B5))&" – "&IF(B6="","",RIGHT("0"&DAY(B6),2)&"."&RIGHT("0"&MONTH(B6),2)&"."&YEAR(B6)) | K2: pomocnicze: | L2: =MIN(COUNTIF('Zgłoszenia'!$Q$5:$Q$504,">0"),100)
L3: =MIN(COUNTIF('Dane rozpisek'!$I$2:$I$2600,">0"),300)
A4: Wózek: | D4: ← wybierz wózek (puste = wszystkie) | L4: =12+L5+3+L3
A5: Od: | B5: =DATE(Rok,Miesiac,1) | D5: ← domyślnie miesiąc z Ustawień; możesz wpisać dowolne daty | L5: =MAX(L2,1)
A6: Do: | B6: =EOMONTH(B5,0)
A8: =COUNTIF('Zgłoszenia'!$Q$5:$Q$504,">0") | C8: =COUNTIFS('Zgłoszenia'!$Q$5:$Q$504,">0",'Zgłoszenia'!$O$5:$O$504,"TAK") | E8: =ROUND(SUMPRODUCT(('Dane rozpisek'!$I$2:$I$2600>0)/(COUNTIFS('Dane rozpisek'!$A$2:$A$2600,'Dane rozpisek'!$A$2:$A$2600,'Dane rozpisek'!$I$2:$I$2600,">0")+('Dane rozpisek'!$I$2:$I$2600=0))),0) | G8: =ROUND(SUMPRODUCT(('Dane rozpisek'!$I$2:$I$2600>0)*('Dane rozpisek'!$E$2:$E$2600<>"")/(COUNTIFS('Dane rozpisek'!$E$2:$E$2600,'Dane rozpisek'!$E$2:$E$2600,'Dane rozpisek'!$I$2:$I$2600,">0")+('Dane rozpisek'!$I$2:$I$2600=0))),0)
A9: Usterek w okresie | C9: Otwartych usterek | E9: Dni w rozpiskach | G9: Różnych operatorów
A11: USTERKI I USZKODZENIA
A12: Data | B12: Wózek | C12: Zmiana | D12: Uderzenie | E12: Co uszkodzone | F12: Kiedy powstało | G12: Operator | H12: Wg rozpiski | I12: Status | J12: Opis
A13: =IF($L13="D",INDEX('Zgłoszenia'!$D$5:$D$504,$M13),IF($L13="U",INDEX('Dane rozpisek'!$A$2:$A$2600,$M13),IF($L13="T","KTO JEŹDZIŁ",IF($L13="E1","Brak zgłoszonych usterek w tym okresie.",IF($L13="E2","Brak wpisów z tym wózkiem w rozpiskach dla tego okresu.",IF($L13="H","Data","")))))) | B13: =IF($L13="D",INDEX('Zgłoszenia'!$B$5:$B$504,$M13)&"",IF($L13="U",INDEX('Dane rozpisek'!$F$2:$F$2600,$M13)&"",IF($L13="H","Wózek",""))) | C13: =IF($L13="D",INDEX('Zgłoszenia'!$E$5:$E$504,$M13)&"",IF($L13="U",INDEX('Dane rozpisek'!$B$2:$B$2600,$M13)&" · "&INDEX('Dane rozpisek'!$J$2:$J$2600,$M13),IF($L13="H","Zmiana",""))) | D13: =IF($L13="D",INDEX('Zgłoszenia'!$H$5:$H$504,$M13)&"",IF($L13="U",INDEX('Dane rozpisek'!$E$2:$E$2600,$M13)&"",IF($L13="H","Operator",""))) | E13: =IF($L13="D",INDEX('Zgłoszenia'!$I$5:$I$504,$M13)&"",IF($L13="U",INDEX('Dane rozpisek'!$C$2:$C$2600,$M13)&"",IF($L13="H","Stanowisko",""))) | F13: =IF($L13="D",INDEX('Zgłoszenia'!$J$5:$J$504,$M13)&"",IF($L13="U",INDEX('Dane rozpisek'!$G$2:$G$2600,$M13)&"",IF($L13="H","Uwagi",""))) | G13: =IF($L13="D",INDEX('Zgłoszenia'!$F$5:$F$504,$M13)&"",IF($L13="U",INDEX('Dane rozpisek'!$L$2:$L$2600,$M13)&"",IF($L13="H","Usterki (dzień / następny)",""))) | H13: =IF($L13="D",INDEX('Zgłoszenia'!$P$5:$P$504,$M13)&"",IF($L13="U","","")) | I13: =IF($L13="D",IF(INDEX('Zgłoszenia'!$M$5:$M$504,$M13)="","Zgłoszona",INDEX('Zgłoszenia'!$M$5:$M$504,$M13)),IF($L13="U","","")) | J13: =IF($L13="D",INDEX('Zgłoszenia'!$K$5:$K$504,$M13)&"",IF($L13="U","","")) | L13: =IF((ROW()-12)<=$L$5,IF($L$2=0,"E1","D"),IF((ROW()-12)=$L$5+1,"",IF((ROW()-12)=$L$5+2,"T",IF((ROW()-12)=$L$5+3,IF($L$3=0,"E2","H"),IF((ROW()-12)<=$L$5+3+$L$3,"U",""))))) | M13: =IF(L13="D",MATCH(LARGE('Zgłoszenia'!$Q$5:$Q$504,(ROW()-12)),'Zgłoszenia'!$Q$5:$Q$504,0),IF(L13="U",MATCH(LARGE('Dane rozpisek'!$I$2:$I$2600,(ROW()-12)-$L$5-3),'Dane rozpisek'!$I$2:$I$2600,0),""))
A14: =IF($L14="D",INDEX('Zgłoszenia'!$D$5:$D$504,$M14),IF($L14="U",INDEX('Dane rozpisek'!$A$2:$A$2600,$M14),IF($L14="T","KTO JEŹDZIŁ",IF($L14="E1","Brak zgłoszonych usterek w tym okresie.",IF($L14="E2","Brak wpisów z tym wózkiem w rozpiskach dla tego okresu.",IF($L14="H","Data","")))))) | B14: =IF($L14="D",INDEX('Zgłoszenia'!$B$5:$B$504,$M14)&"",IF($L14="U",INDEX('Dane rozpisek'!$F$2:$F$2600,$M14)&"",IF($L14="H","Wózek",""))) | C14: =IF($L14="D",INDEX('Zgłoszenia'!$E$5:$E$504,$M14)&"",IF($L14="U",INDEX('Dane rozpisek'!$B$2:$B$2600,$M14)&" · "&INDEX('Dane rozpisek'!$J$2:$J$2600,$M14),IF($L14="H","Zmiana",""))) | D14: =IF($L14="D",INDEX('Zgłoszenia'!$H$5:$H$504,$M14)&"",IF($L14="U",INDEX('Dane rozpisek'!$E$2:$E$2600,$M14)&"",IF($L14="H","Operator",""))) | E14: =IF($L14="D",INDEX('Zgłoszenia'!$I$5:$I$504,$M14)&"",IF($L14="U",INDEX('Dane rozpisek'!$C$2:$C$2600,$M14)&"",IF($L14="H","Stanowisko",""))) | F14: =IF($L14="D",INDEX('Zgłoszenia'!$J$5:$J$504,$M14)&"",IF($L14="U",INDEX('Dane rozpisek'!$G$2:$G$2600,$M14)&"",IF($L14="H","Uwagi",""))) | G14: =IF($L14="D",INDEX('Zgłoszenia'!$F$5:$F$504,$M14)&"",IF($L14="U",INDEX('Dane rozpisek'!$L$2:$L$2600,$M14)&"",IF($L14="H","Usterki (dzień / następny)",""))) | H14: =IF($L14="D",INDEX('Zgłoszenia'!$P$5:$P$504,$M14)&"",IF($L14="U","","")) | I14: =IF($L14="D",IF(INDEX('Zgłoszenia'!$M$5:$M$504,$M14)="","Zgłoszona",INDEX('Zgłoszenia'!$M$5:$M$504,$M14)),IF($L14="U","","")) | J14: =IF($L14="D",INDEX('Zgłoszenia'!$K$5:$K$504,$M14)&"",IF($L14="U","","")) | L14: =IF((ROW()-12)<=$L$5,IF($L$2=0,"E1","D"),IF((ROW()-12)=$L$5+1,"",IF((ROW()-12)=$L$5+2,"T",IF((ROW()-12)=$L$5+3,IF($L$3=0,"E2","H"),IF((ROW()-12)<=$L$5+3+$L$3,"U",""))))) | M14: =IF(L14="D",MATCH(LARGE('Zgłoszenia'!$Q$5:$Q$504,(ROW()-12)),'Zgłoszenia'!$Q$5:$Q$504,0),IF(L14="U",MATCH(LARGE('Dane rozpisek'!$I$2:$I$2600,(ROW()-12)-$L$5-3),'Dane rozpisek'!$I$2:$I$2600,0),""))
A15: =IF($L15="D",INDEX('Zgłoszenia'!$D$5:$D$504,$M15),IF($L15="U",INDEX('Dane rozpisek'!$A$2:$A$2600,$M15),IF($L15="T","KTO JEŹDZIŁ",IF($L15="E1","Brak zgłoszonych usterek w tym okresie.",IF($L15="E2","Brak wpisów z tym wózkiem w rozpiskach dla tego okresu.",IF($L15="H","Data","")))))) | B15: =IF($L15="D",INDEX('Zgłoszenia'!$B$5:$B$504,$M15)&"",IF($L15="U",INDEX('Dane rozpisek'!$F$2:$F$2600,$M15)&"",IF($L15="H","Wózek",""))) | C15: =IF($L15="D",INDEX('Zgłoszenia'!$E$5:$E$504,$M15)&"",IF($L15="U",INDEX('Dane rozpisek'!$B$2:$B$2600,$M15)&" · "&INDEX('Dane rozpisek'!$J$2:$J$2600,$M15),IF($L15="H","Zmiana",""))) | D15: =IF($L15="D",INDEX('Zgłoszenia'!$H$5:$H$504,$M15)&"",IF($L15="U",INDEX('Dane rozpisek'!$E$2:$E$2600,$M15)&"",IF($L15="H","Operator",""))) | E15: =IF($L15="D",INDEX('Zgłoszenia'!$I$5:$I$504,$M15)&"",IF($L15="U",INDEX('Dane rozpisek'!$C$2:$C$2600,$M15)&"",IF($L15="H","Stanowisko",""))) | F15: =IF($L15="D",INDEX('Zgłoszenia'!$J$5:$J$504,$M15)&"",IF($L15="U",INDEX('Dane rozpisek'!$G$2:$G$2600,$M15)&"",IF($L15="H","Uwagi",""))) | G15: =IF($L15="D",INDEX('Zgłoszenia'!$F$5:$F$504,$M15)&"",IF($L15="U",INDEX('Dane rozpisek'!$L$2:$L$2600,$M15)&"",IF($L15="H","Usterki (dzień / następny)",""))) | H15: =IF($L15="D",INDEX('Zgłoszenia'!$P$5:$P$504,$M15)&"",IF($L15="U","","")) | I15: =IF($L15="D",IF(INDEX('Zgłoszenia'!$M$5:$M$504,$M15)="","Zgłoszona",INDEX('Zgłoszenia'!$M$5:$M$504,$M15)),IF($L15="U","","")) | J15: =IF($L15="D",INDEX('Zgłoszenia'!$K$5:$K$504,$M15)&"",IF($L15="U","","")) | L15: =IF((ROW()-12)<=$L$5,IF($L$2=0,"E1","D"),IF((ROW()-12)=$L$5+1,"",IF((ROW()-12)=$L$5+2,"T",IF((ROW()-12)=$L$5+3,IF($L$3=0,"E2","H"),IF((ROW()-12)<=$L$5+3+$L$3,"U",""))))) | M15: =IF(L15="D",MATCH(LARGE('Zgłoszenia'!$Q$5:$Q$504,(ROW()-12)),'Zgłoszenia'!$Q$5:$Q$504,0),IF(L15="U",MATCH(LARGE('Dane rozpisek'!$I$2:$I$2600,(ROW()-12)-$L$5-3),'Dane rozpisek'!$I$2:$I$2600,0),""))
A16: =IF($L16="D",INDEX('Zgłoszenia'!$D$5:$D$504,$M16),IF($L16="U",INDEX('Dane rozpisek'!$A$2:$A$2600,$M16),IF($L16="T","KTO JEŹDZIŁ",IF($L16="E1","Brak zgłoszonych usterek w tym okresie.",IF($L16="E2","Brak wpisów z tym wózkiem w rozpiskach dla tego okresu.",IF($L16="H","Data","")))))) | B16: =IF($L16="D",INDEX('Zgłoszenia'!$B$5:$B$504,$M16)&"",IF($L16="U",INDEX('Dane rozpisek'!$F$2:$F$2600,$M16)&"",IF($L16="H","Wózek",""))) | C16: =IF($L16="D",INDEX('Zgłoszenia'!$E$5:$E$504,$M16)&"",IF($L16="U",INDEX('Dane rozpisek'!$B$2:$B$2600,$M16)&" · "&INDEX('Dane rozpisek'!$J$2:$J$2600,$M16),IF($L16="H","Zmiana",""))) | D16: =IF($L16="D",INDEX('Zgłoszenia'!$H$5:$H$504,$M16)&"",IF($L16="U",INDEX('Dane rozpisek'!$E$2:$E$2600,$M16)&"",IF($L16="H","Operator",""))) | E16: =IF($L16="D",INDEX('Zgłoszenia'!$I$5:$I$504,$M16)&"",IF($L16="U",INDEX('Dane rozpisek'!$C$2:$C$2600,$M16)&"",IF($L16="H","Stanowisko",""))) | F16: =IF($L16="D",INDEX('Zgłoszenia'!$J$5:$J$504,$M16)&"",IF($L16="U",INDEX('Dane rozpisek'!$G$2:$G$2600,$M16)&"",IF($L16="H","Uwagi",""))) | G16: =IF($L16="D",INDEX('Zgłoszenia'!$F$5:$F$504,$M16)&"",IF($L16="U",INDEX('Dane rozpisek'!$L$2:$L$2600,$M16)&"",IF($L16="H","Usterki (dzień / następny)",""))) | H16: =IF($L16="D",INDEX('Zgłoszenia'!$P$5:$P$504,$M16)&"",IF($L16="U","","")) | I16: =IF($L16="D",IF(INDEX('Zgłoszenia'!$M$5:$M$504,$M16)="","Zgłoszona",INDEX('Zgłoszenia'!$M$5:$M$504,$M16)),IF($L16="U","","")) | J16: =IF($L16="D",INDEX('Zgłoszenia'!$K$5:$K$504,$M16)&"",IF($L16="U","","")) | L16: =IF((ROW()-12)<=$L$5,IF($L$2=0,"E1","D"),IF((ROW()-12)=$L$5+1,"",IF((ROW()-12)=$L$5+2,"T",IF((ROW()-12)=$L$5+3,IF($L$3=0,"E2","H"),IF((ROW()-12)<=$L$5+3+$L$3,"U",""))))) | M16: =IF(L16="D",MATCH(LARGE('Zgłoszenia'!$Q$5:$Q$504,(ROW()-12)),'Zgłoszenia'!$Q$5:$Q$504,0),IF(L16="U",MATCH(LARGE('Dane rozpisek'!$I$2:$I$2600,(ROW()-12)-$L$5-3),'Dane rozpisek'!$I$2:$I$2600,0),""))
A17: =IF($L17="D",INDEX('Zgłoszenia'!$D$5:$D$504,$M17),IF($L17="U",INDEX('Dane rozpisek'!$A$2:$A$2600,$M17),IF($L17="T","KTO JEŹDZIŁ",IF($L17="E1","Brak zgłoszonych usterek w tym okresie.",IF($L17="E2","Brak wpisów z tym wózkiem w rozpiskach dla tego okresu.",IF($L17="H","Data","")))))) | B17: =IF($L17="D",INDEX('Zgłoszenia'!$B$5:$B$504,$M17)&"",IF($L17="U",INDEX('Dane rozpisek'!$F$2:$F$2600,$M17)&"",IF($L17="H","Wózek",""))) | C17: =IF($L17="D",INDEX('Zgłoszenia'!$E$5:$E$504,$M17)&"",IF($L17="U",INDEX('Dane rozpisek'!$B$2:$B$2600,$M17)&" · "&INDEX('Dane rozpisek'!$J$2:$J$2600,$M17),IF($L17="H","Zmiana",""))) | D17: =IF($L17="D",INDEX('Zgłoszenia'!$H$5:$H$504,$M17)&"",IF($L17="U",INDEX('Dane rozpisek'!$E$2:$E$2600,$M17)&"",IF($L17="H","Operator",""))) | E17: =IF($L17="D",INDEX('Zgłoszenia'!$I$5:$I$504,$M17)&"",IF($L17="U",INDEX('Dane rozpisek'!$C$2:$C$2600,$M17)&"",IF($L17="H","Stanowisko",""))) | F17: =IF($L17="D",INDEX('Zgłoszenia'!$J$5:$J$504,$M17)&"",IF($L17="U",INDEX('Dane rozpisek'!$G$2:$G$2600,$M17)&"",IF($L17="H","Uwagi",""))) | G17: =IF($L17="D",INDEX('Zgłoszenia'!$F$5:$F$504,$M17)&"",IF($L17="U",INDEX('Dane rozpisek'!$L$2:$L$2600,$M17)&"",IF($L17="H","Usterki (dzień / następny)",""))) | H17: =IF($L17="D",INDEX('Zgłoszenia'!$P$5:$P$504,$M17)&"",IF($L17="U","","")) | I17: =IF($L17="D",IF(INDEX('Zgłoszenia'!$M$5:$M$504,$M17)="","Zgłoszona",INDEX('Zgłoszenia'!$M$5:$M$504,$M17)),IF($L17="U","","")) | J17: =IF($L17="D",INDEX('Zgłoszenia'!$K$5:$K$504,$M17)&"",IF($L17="U","","")) | L17: =IF((ROW()-12)<=$L$5,IF($L$2=0,"E1","D"),IF((ROW()-12)=$L$5+1,"",IF((ROW()-12)=$L$5+2,"T",IF((ROW()-12)=$L$5+3,IF($L$3=0,"E2","H"),IF((ROW()-12)<=$L$5+3+$L$3,"U",""))))) | M17: =IF(L17="D",MATCH(LARGE('Zgłoszenia'!$Q$5:$Q$504,(ROW()-12)),'Zgłoszenia'!$Q$5:$Q$504,0),IF(L17="U",MATCH(LARGE('Dane rozpisek'!$I$2:$I$2600,(ROW()-12)-$L$5-3),'Dane rozpisek'!$I$2:$I$2600,0),""))
A18: =IF($L18="D",INDEX('Zgłoszenia'!$D$5:$D$504,$M18),IF($L18="U",INDEX('Dane rozpisek'!$A$2:$A$2600,$M18),IF($L18="T","KTO JEŹDZIŁ",IF($L18="E1","Brak zgłoszonych usterek w tym okresie.",IF($L18="E2","Brak wpisów z tym wózkiem w rozpiskach dla tego okresu.",IF($L18="H","Data","")))))) | B18: =IF($L18="D",INDEX('Zgłoszenia'!$B$5:$B$504,$M18)&"",IF($L18="U",INDEX('Dane rozpisek'!$F$2:$F$2600,$M18)&"",IF($L18="H","Wózek",""))) | C18: =IF($L18="D",INDEX('Zgłoszenia'!$E$5:$E$504,$M18)&"",IF($L18="U",INDEX('Dane rozpisek'!$B$2:$B$2600,$M18)&" · "&INDEX('Dane rozpisek'!$J$2:$J$2600,$M18),IF($L18="H","Zmiana",""))) | D18: =IF($L18="D",INDEX('Zgłoszenia'!$H$5:$H$504,$M18)&"",IF($L18="U",INDEX('Dane rozpisek'!$E$2:$E$2600,$M18)&"",IF($L18="H","Operator",""))) | E18: =IF($L18="D",INDEX('Zgłoszenia'!$I$5:$I$504,$M18)&"",IF($L18="U",INDEX('Dane rozpisek'!$C$2:$C$2600,$M18)&"",IF($L18="H","Stanowisko",""))) | F18: =IF($L18="D",INDEX('Zgłoszenia'!$J$5:$J$504,$M18)&"",IF($L18="U",INDEX('Dane rozpisek'!$G$2:$G$2600,$M18)&"",IF($L18="H","Uwagi",""))) | G18: =IF($L18="D",INDEX('Zgłoszenia'!$F$5:$F$504,$M18)&"",IF($L18="U",INDEX('Dane rozpisek'!$L$2:$L$2600,$M18)&"",IF($L18="H","Usterki (dzień / następny)",""))) | H18: =IF($L18="D",INDEX('Zgłoszenia'!$P$5:$P$504,$M18)&"",IF($L18="U","","")) | I18: =IF($L18="D",IF(INDEX('Zgłoszenia'!$M$5:$M$504,$M18)="","Zgłoszona",INDEX('Zgłoszenia'!$M$5:$M$504,$M18)),IF($L18="U","","")) | J18: =IF($L18="D",INDEX('Zgłoszenia'!$K$5:$K$504,$M18)&"",IF($L18="U","","")) | L18: =IF((ROW()-12)<=$L$5,IF($L$2=0,"E1","D"),IF((ROW()-12)=$L$5+1,"",IF((ROW()-12)=$L$5+2,"T",IF((ROW()-12)=$L$5+3,IF($L$3=0,"E2","H"),IF((ROW()-12)<=$L$5+3+$L$3,"U",""))))) | M18: =IF(L18="D",MATCH(LARGE('Zgłoszenia'!$Q$5:$Q$504,(ROW()-12)),'Zgłoszenia'!$Q$5:$Q$504,0),IF(L18="U",MATCH(LARGE('Dane rozpisek'!$I$2:$I$2600,(ROW()-12)-$L$5-3),'Dane rozpisek'!$I$2:$I$2600,0),""))
A19: =IF($L19="D",INDEX('Zgłoszenia'!$D$5:$D$504,$M19),IF($L19="U",INDEX('Dane rozpisek'!$A$2:$A$2600,$M19),IF($L19="T","KTO JEŹDZIŁ",IF($L19="E1","Brak zgłoszonych usterek w tym okresie.",IF($L19="E2","Brak wpisów z tym wózkiem w rozpiskach dla tego okresu.",IF($L19="H","Data","")))))) | B19: =IF($L19="D",INDEX('Zgłoszenia'!$B$5:$B$504,$M19)&"",IF($L19="U",INDEX('Dane rozpisek'!$F$2:$F$2600,$M19)&"",IF($L19="H","Wózek",""))) | C19: =IF($L19="D",INDEX('Zgłoszenia'!$E$5:$E$504,$M19)&"",IF($L19="U",INDEX('Dane rozpisek'!$B$2:$B$2600,$M19)&" · "&INDEX('Dane rozpisek'!$J$2:$J$2600,$M19),IF($L19="H","Zmiana",""))) | D19: =IF($L19="D",INDEX('Zgłoszenia'!$H$5:$H$504,$M19)&"",IF($L19="U",INDEX('Dane rozpisek'!$E$2:$E$2600,$M19)&"",IF($L19="H","Operator",""))) | E19: =IF($L19="D",INDEX('Zgłoszenia'!$I$5:$I$504,$M19)&"",IF($L19="U",INDEX('Dane rozpisek'!$C$2:$C$2600,$M19)&"",IF($L19="H","Stanowisko",""))) | F19: =IF($L19="D",INDEX('Zgłoszenia'!$J$5:$J$504,$M19)&"",IF($L19="U",INDEX('Dane rozpisek'!$G$2:$G$2600,$M19)&"",IF($L19="H","Uwagi",""))) | G19: =IF($L19="D",INDEX('Zgłoszenia'!$F$5:$F$504,$M19)&"",IF($L19="U",INDEX('Dane rozpisek'!$L$2:$L$2600,$M19)&"",IF($L19="H","Usterki (dzień / następny)",""))) | H19: =IF($L19="D",INDEX('Zgłoszenia'!$P$5:$P$504,$M19)&"",IF($L19="U","","")) | I19: =IF($L19="D",IF(INDEX('Zgłoszenia'!$M$5:$M$504,$M19)="","Zgłoszona",INDEX('Zgłoszenia'!$M$5:$M$504,$M19)),IF($L19="U","","")) | J19: =IF($L19="D",INDEX('Zgłoszenia'!$K$5:$K$504,$M19)&"",IF($L19="U","","")) | L19: =IF((ROW()-12)<=$L$5,IF($L$2=0,"E1","D"),IF((ROW()-12)=$L$5+1,"",IF((ROW()-12)=$L$5+2,"T",IF((ROW()-12)=$L$5+3,IF($L$3=0,"E2","H"),IF((ROW()-12)<=$L$5+3+$L$3,"U",""))))) | M19: =IF(L19="D",MATCH(LARGE('Zgłoszenia'!$Q$5:$Q$504,(ROW()-12)),'Zgłoszenia'!$Q$5:$Q$504,0),IF(L19="U",MATCH(LARGE('Dane rozpisek'!$I$2:$I$2600,(ROW()-12)-$L$5-3),'Dane rozpisek'!$I$2:$I$2600,0),""))
A20: =IF($L20="D",INDEX('Zgłoszenia'!$D$5:$D$504,$M20),IF($L20="U",INDEX('Dane rozpisek'!$A$2:$A$2600,$M20),IF($L20="T","KTO JEŹDZIŁ",IF($L20="E1","Brak zgłoszonych usterek w tym okresie.",IF($L20="E2","Brak wpisów z tym wózkiem w rozpiskach dla tego okresu.",IF($L20="H","Data","")))))) | B20: =IF($L20="D",INDEX('Zgłoszenia'!$B$5:$B$504,$M20)&"",IF($L20="U",INDEX('Dane rozpisek'!$F$2:$F$2600,$M20)&"",IF($L20="H","Wózek",""))) | C20: =IF($L20="D",INDEX('Zgłoszenia'!$E$5:$E$504,$M20)&"",IF($L20="U",INDEX('Dane rozpisek'!$B$2:$B$2600,$M20)&" · "&INDEX('Dane rozpisek'!$J$2:$J$2600,$M20),IF($L20="H","Zmiana",""))) | D20: =IF($L20="D",INDEX('Zgłoszenia'!$H$5:$H$504,$M20)&"",IF($L20="U",INDEX('Dane rozpisek'!$E$2:$E$2600,$M20)&"",IF($L20="H","Operator",""))) | E20: =IF($L20="D",INDEX('Zgłoszenia'!$I$5:$I$504,$M20)&"",IF($L20="U",INDEX('Dane rozpisek'!$C$2:$C$2600,$M20)&"",IF($L20="H","Stanowisko",""))) | F20: =IF($L20="D",INDEX('Zgłoszenia'!$J$5:$J$504,$M20)&"",IF($L20="U",INDEX('Dane rozpisek'!$G$2:$G$2600,$M20)&"",IF($L20="H","Uwagi",""))) | G20: =IF($L20="D",INDEX('Zgłoszenia'!$F$5:$F$504,$M20)&"",IF($L20="U",INDEX('Dane rozpisek'!$L$2:$L$2600,$M20)&"",IF($L20="H","Usterki (dzień / następny)",""))) | H20: =IF($L20="D",INDEX('Zgłoszenia'!$P$5:$P$504,$M20)&"",IF($L20="U","","")) | I20: =IF($L20="D",IF(INDEX('Zgłoszenia'!$M$5:$M$504,$M20)="","Zgłoszona",INDEX('Zgłoszenia'!$M$5:$M$504,$M20)),IF($L20="U","","")) | J20: =IF($L20="D",INDEX('Zgłoszenia'!$K$5:$K$504,$M20)&"",IF($L20="U","","")) | L20: =IF((ROW()-12)<=$L$5,IF($L$2=0,"E1","D"),IF((ROW()-12)=$L$5+1,"",IF((ROW()-12)=$L$5+2,"T",IF((ROW()-12)=$L$5+3,IF($L$3=0,"E2","H"),IF((ROW()-12)<=$L$5+3+$L$3,"U",""))))) | M20: =IF(L20="D",MATCH(LARGE('Zgłoszenia'!$Q$5:$Q$504,(ROW()-12)),'Zgłoszenia'!$Q$5:$Q$504,0),IF(L20="U",MATCH(LARGE('Dane rozpisek'!$I$2:$I$2600,(ROW()-12)-$L$5-3),'Dane rozpisek'!$I$2:$I$2600,0),""))
A21: =IF($L21="D",INDEX('Zgłoszenia'!$D$5:$D$504,$M21),IF($L21="U",INDEX('Dane rozpisek'!$A$2:$A$2600,$M21),IF($L21="T","KTO JEŹDZIŁ",IF($L21="E1","Brak zgłoszonych usterek w tym okresie.",IF($L21="E2","Brak wpisów z tym wózkiem w rozpiskach dla tego okresu.",IF($L21="H","Data","")))))) | B21: =IF($L21="D",INDEX('Zgłoszenia'!$B$5:$B$504,$M21)&"",IF($L21="U",INDEX('Dane rozpisek'!$F$2:$F$2600,$M21)&"",IF($L21="H","Wózek",""))) | C21: =IF($L21="D",INDEX('Zgłoszenia'!$E$5:$E$504,$M21)&"",IF($L21="U",INDEX('Dane rozpisek'!$B$2:$B$2600,$M21)&" · "&INDEX('Dane rozpisek'!$J$2:$J$2600,$M21),IF($L21="H","Zmiana",""))) | D21: =IF($L21="D",INDEX('Zgłoszenia'!$H$5:$H$504,$M21)&"",IF($L21="U",INDEX('Dane rozpisek'!$E$2:$E$2600,$M21)&"",IF($L21="H","Operator",""))) | E21: =IF($L21="D",INDEX('Zgłoszenia'!$I$5:$I$504,$M21)&"",IF($L21="U",INDEX('Dane rozpisek'!$C$2:$C$2600,$M21)&"",IF($L21="H","Stanowisko",""))) | F21: =IF($L21="D",INDEX('Zgłoszenia'!$J$5:$J$504,$M21)&"",IF($L21="U",INDEX('Dane rozpisek'!$G$2:$G$2600,$M21)&"",IF($L21="H","Uwagi",""))) | G21: =IF($L21="D",INDEX('Zgłoszenia'!$F$5:$F$504,$M21)&"",IF($L21="U",INDEX('Dane rozpisek'!$L$2:$L$2600,$M21)&"",IF($L21="H","Usterki (dzień / następny)",""))) | H21: =IF($L21="D",INDEX('Zgłoszenia'!$P$5:$P$504,$M21)&"",IF($L21="U","","")) | I21: =IF($L21="D",IF(INDEX('Zgłoszenia'!$M$5:$M$504,$M21)="","Zgłoszona",INDEX('Zgłoszenia'!$M$5:$M$504,$M21)),IF($L21="U","","")) | J21: =IF($L21="D",INDEX('Zgłoszenia'!$K$5:$K$504,$M21)&"",IF($L21="U","","")) | L21: =IF((ROW()-12)<=$L$5,IF($L$2=0,"E1","D"),IF((ROW()-12)=$L$5+1,"",IF((ROW()-12)=$L$5+2,"T",IF((ROW()-12)=$L$5+3,IF($L$3=0,"E2","H"),IF((ROW()-12)<=$L$5+3+$L$3,"U",""))))) | M21: =IF(L21="D",MATCH(LARGE('Zgłoszenia'!$Q$5:$Q$504,(ROW()-12)),'Zgłoszenia'!$Q$5:$Q$504,0),IF(L21="U",MATCH(LARGE('Dane rozpisek'!$I$2:$I$2600,(ROW()-12)-$L$5-3),'Dane rozpisek'!$I$2:$I$2600,0),""))
A22: =IF($L22="D",INDEX('Zgłoszenia'!$D$5:$D$504,$M22),IF($L22="U",INDEX('Dane rozpisek'!$A$2:$A$2600,$M22),IF($L22="T","KTO JEŹDZIŁ",IF($L22="E1","Brak zgłoszonych usterek w tym okresie.",IF($L22="E2","Brak wpisów z tym wózkiem w rozpiskach dla tego okresu.",IF($L22="H","Data","")))))) | B22: =IF($L22="D",INDEX('Zgłoszenia'!$B$5:$B$504,$M22)&"",IF($L22="U",INDEX('Dane rozpisek'!$F$2:$F$2600,$M22)&"",IF($L22="H","Wózek",""))) | C22: =IF($L22="D",INDEX('Zgłoszenia'!$E$5:$E$504,$M22)&"",IF($L22="U",INDEX('Dane rozpisek'!$B$2:$B$2600,$M22)&" · "&INDEX('Dane rozpisek'!$J$2:$J$2600,$M22),IF($L22="H","Zmiana",""))) | D22: =IF($L22="D",INDEX('Zgłoszenia'!$H$5:$H$504,$M22)&"",IF($L22="U",INDEX('Dane rozpisek'!$E$2:$E$2600,$M22)&"",IF($L22="H","Operator",""))) | E22: =IF($L22="D",INDEX('Zgłoszenia'!$I$5:$I$504,$M22)&"",IF($L22="U",INDEX('Dane rozpisek'!$C$2:$C$2600,$M22)&"",IF($L22="H","Stanowisko",""))) | F22: =IF($L22="D",INDEX('Zgłoszenia'!$J$5:$J$504,$M22)&"",IF($L22="U",INDEX('Dane rozpisek'!$G$2:$G$2600,$M22)&"",IF($L22="H","Uwagi",""))) | G22: =IF($L22="D",INDEX('Zgłoszenia'!$F$5:$F$504,$M22)&"",IF($L22="U",INDEX('Dane rozpisek'!$L$2:$L$2600,$M22)&"",IF($L22="H","Usterki (dzień / następny)",""))) | H22: =IF($L22="D",INDEX('Zgłoszenia'!$P$5:$P$504,$M22)&"",IF($L22="U","","")) | I22: =IF($L22="D",IF(INDEX('Zgłoszenia'!$M$5:$M$504,$M22)="","Zgłoszona",INDEX('Zgłoszenia'!$M$5:$M$504,$M22)),IF($L22="U","","")) | J22: =IF($L22="D",INDEX('Zgłoszenia'!$K$5:$K$504,$M22)&"",IF($L22="U","","")) | L22: =IF((ROW()-12)<=$L$5,IF($L$2=0,"E1","D"),IF((ROW()-12)=$L$5+1,"",IF((ROW()-12)=$L$5+2,"T",IF((ROW()-12)=$L$5+3,IF($L$3=0,"E2","H"),IF((ROW()-12)<=$L$5+3+$L$3,"U",""))))) | M22: =IF(L22="D",MATCH(LARGE('Zgłoszenia'!$Q$5:$Q$504,(ROW()-12)),'Zgłoszenia'!$Q$5:$Q$504,0),IF(L22="U",MATCH(LARGE('Dane rozpisek'!$I$2:$I$2600,(ROW()-12)-$L$5-3),'Dane rozpisek'!$I$2:$I$2600,0),""))
A23: =IF($L23="D",INDEX('Zgłoszenia'!$D$5:$D$504,$M23),IF($L23="U",INDEX('Dane rozpisek'!$A$2:$A$2600,$M23),IF($L23="T","KTO JEŹDZIŁ",IF($L23="E1","Brak zgłoszonych usterek w tym okresie.",IF($L23="E2","Brak wpisów z tym wózkiem w rozpiskach dla tego okresu.",IF($L23="H","Data","")))))) | B23: =IF($L23="D",INDEX('Zgłoszenia'!$B$5:$B$504,$M23)&"",IF($L23="U",INDEX('Dane rozpisek'!$F$2:$F$2600,$M23)&"",IF($L23="H","Wózek",""))) | C23: =IF($L23="D",INDEX('Zgłoszenia'!$E$5:$E$504,$M23)&"",IF($L23="U",INDEX('Dane rozpisek'!$B$2:$B$2600,$M23)&" · "&INDEX('Dane rozpisek'!$J$2:$J$2600,$M23),IF($L23="H","Zmiana",""))) | D23: =IF($L23="D",INDEX('Zgłoszenia'!$H$5:$H$504,$M23)&"",IF($L23="U",INDEX('Dane rozpisek'!$E$2:$E$2600,$M23)&"",IF($L23="H","Operator",""))) | E23: =IF($L23="D",INDEX('Zgłoszenia'!$I$5:$I$504,$M23)&"",IF($L23="U",INDEX('Dane rozpisek'!$C$2:$C$2600,$M23)&"",IF($L23="H","Stanowisko",""))) | F23: =IF($L23="D",INDEX('Zgłoszenia'!$J$5:$J$504,$M23)&"",IF($L23="U",INDEX('Dane rozpisek'!$G$2:$G$2600,$M23)&"",IF($L23="H","Uwagi",""))) | G23: =IF($L23="D",INDEX('Zgłoszenia'!$F$5:$F$504,$M23)&"",IF($L23="U",INDEX('Dane rozpisek'!$L$2:$L$2600,$M23)&"",IF($L23="H","Usterki (dzień / następny)",""))) | H23: =IF($L23="D",INDEX('Zgłoszenia'!$P$5:$P$504,$M23)&"",IF($L23="U","","")) | I23: =IF($L23="D",IF(INDEX('Zgłoszenia'!$M$5:$M$504,$M23)="","Zgłoszona",INDEX('Zgłoszenia'!$M$5:$M$504,$M23)),IF($L23="U","","")) | J23: =IF($L23="D",INDEX('Zgłoszenia'!$K$5:$K$504,$M23)&"",IF($L23="U","","")) | L23: =IF((ROW()-12)<=$L$5,IF($L$2=0,"E1","D"),IF((ROW()-12)=$L$5+1,"",IF((ROW()-12)=$L$5+2,"T",IF((ROW()-12)=$L$5+3,IF($L$3=0,"E2","H"),IF((ROW()-12)<=$L$5+3+$L$3,"U",""))))) | M23: =IF(L23="D",MATCH(LARGE('Zgłoszenia'!$Q$5:$Q$504,(ROW()-12)),'Zgłoszenia'!$Q$5:$Q$504,0),IF(L23="U",MATCH(LARGE('Dane rozpisek'!$I$2:$I$2600,(ROW()-12)-$L$5-3),'Dane rozpisek'!$I$2:$I$2600,0),""))
A24: =IF($L24="D",INDEX('Zgłoszenia'!$D$5:$D$504,$M24),IF($L24="U",INDEX('Dane rozpisek'!$A$2:$A$2600,$M24),IF($L24="T","KTO JEŹDZIŁ",IF($L24="E1","Brak zgłoszonych usterek w tym okresie.",IF($L24="E2","Brak wpisów z tym wózkiem w rozpiskach dla tego okresu.",IF($L24="H","Data","")))))) | B24: =IF($L24="D",INDEX('Zgłoszenia'!$B$5:$B$504,$M24)&"",IF($L24="U",INDEX('Dane rozpisek'!$F$2:$F$2600,$M24)&"",IF($L24="H","Wózek",""))) | C24: =IF($L24="D",INDEX('Zgłoszenia'!$E$5:$E$504,$M24)&"",IF($L24="U",INDEX('Dane rozpisek'!$B$2:$B$2600,$M24)&" · "&INDEX('Dane rozpisek'!$J$2:$J$2600,$M24),IF($L24="H","Zmiana",""))) | D24: =IF($L24="D",INDEX('Zgłoszenia'!$H$5:$H$504,$M24)&"",IF($L24="U",INDEX('Dane rozpisek'!$E$2:$E$2600,$M24)&"",IF($L24="H","Operator",""))) | E24: =IF($L24="D",INDEX('Zgłoszenia'!$I$5:$I$504,$M24)&"",IF($L24="U",INDEX('Dane rozpisek'!$C$2:$C$2600,$M24)&"",IF($L24="H","Stanowisko",""))) | F24: =IF($L24="D",INDEX('Zgłoszenia'!$J$5:$J$504,$M24)&"",IF($L24="U",INDEX('Dane rozpisek'!$G$2:$G$2600,$M24)&"",IF($L24="H","Uwagi",""))) | G24: =IF($L24="D",INDEX('Zgłoszenia'!$F$5:$F$504,$M24)&"",IF($L24="U",INDEX('Dane rozpisek'!$L$2:$L$2600,$M24)&"",IF($L24="H","Usterki (dzień / następny)",""))) | H24: =IF($L24="D",INDEX('Zgłoszenia'!$P$5:$P$504,$M24)&"",IF($L24="U","","")) | I24: =IF($L24="D",IF(INDEX('Zgłoszenia'!$M$5:$M$504,$M24)="","Zgłoszona",INDEX('Zgłoszenia'!$M$5:$M$504,$M24)),IF($L24="U","","")) | J24: =IF($L24="D",INDEX('Zgłoszenia'!$K$5:$K$504,$M24)&"",IF($L24="U","","")) | L24: =IF((ROW()-12)<=$L$5,IF($L$2=0,"E1","D"),IF((ROW()-12)=$L$5+1,"",IF((ROW()-12)=$L$5+2,"T",IF((ROW()-12)=$L$5+3,IF($L$3=0,"E2","H"),IF((ROW()-12)<=$L$5+3+$L$3,"U",""))))) | M24: =IF(L24="D",MATCH(LARGE('Zgłoszenia'!$Q$5:$Q$504,(ROW()-12)),'Zgłoszenia'!$Q$5:$Q$504,0),IF(L24="U",MATCH(LARGE('Dane rozpisek'!$I$2:$I$2600,(ROW()-12)-$L$5-3),'Dane rozpisek'!$I$2:$I$2600,0),""))
... A415: =IF($L415="D",INDEX('Zgłoszenia'!$D$5:$D$504,$M415),IF($L415="U",INDEX('Dane rozpisek'!$A$2:$A$2600,$M415),IF($L415="T","KTO JEŹDZIŁ",IF($L415="E1","Brak zgłoszonych usterek w tym okresie.",IF($L415="E2","Brak wpisów z tym wózkiem w rozpiskach dla tego okresu.",IF($L415="H","Data","")))))) | B415: =IF($L415="D",INDEX('Zgłoszenia'!$B$5:$B$504,$M415)&"",IF($L415="U",INDEX('Dane rozpisek'!$F$2:$F$2600,$M415)&"",IF($L415="H","Wózek",""))) | C415: =IF($L415="D",INDEX('Zgłoszenia'!$E$5:$E$504,$M415)&"",IF($L415="U",INDEX('Dane rozpisek'!$B$2:$B$2600,$M415)&" · "&INDEX('Dane rozpisek'!$J$2:$J$2600,$M415),IF($L415="H","Zmiana",""))) | D415: =IF($L415="D",INDEX('Zgłoszenia'!$H$5:$H$504,$M415)&"",IF($L415="U",INDEX('Dane rozpisek'!$E$2:$E$2600,$M415)&"",IF($L415="H","Operator",""))) | E415: =IF($L415="D",INDEX('Zgłoszenia'!$I$5:$I$504,$M415)&"",IF($L415="U",INDEX('Dane rozpisek'!$C$2:$C$2600,$M415)&"",IF($L415="H","Stanowisko",""))) | F415: =IF($L415="D",INDEX('Zgłoszenia'!$J$5:$J$504,$M415)&"",IF($L415="U",INDEX('Dane rozpisek'!$G$2:$G$2600,$M415)&"",IF($L415="H","Uwagi",""))) | G415: =IF($L415="D",INDEX('Zgłoszenia'!$F$5:$F$504,$M415)&"",IF($L415="U",INDEX('Dane rozpisek'!$L$2:$L$2600,$M415)&"",IF($L415="H","Usterki (dzień / następny)",""))) | H415: =IF($L415="D",INDEX('Zgłoszenia'!$P$5:$P$504,$M415)&"",IF($L415="U","","")) | I415: =IF($L415="D",IF(INDEX('Zgłoszenia'!$M$5:$M$504,$M415)="","Zgłoszona",INDEX('Zgłoszenia'!$M$5:$M$504,$M415)),IF($L415="U","","")) | J415: =IF($L415="D",INDEX('Zgłoszenia'!$K$5:$K$504,$M415)&"",IF($L415="U","","")) | L415: =IF((ROW()-12)<=$L$5,IF($L$2=0,"E1","D"),IF((ROW()-12)=$L$5+1,"",IF((ROW()-12)=$L$5+2,"T",IF((ROW()-12)=$L$5+3,IF($L$3=0,"E2","H"),IF((ROW()-12)<=$L$5+3+$L$3,"U",""))))) | M415: =IF(L415="D",MATCH(LARGE('Zgłoszenia'!$Q$5:$Q$504,(ROW()-12)),'Zgłoszenia'!$Q$5:$Q$504,0),IF(L415="U",MATCH(LARGE('Dane rozpisek'!$I$2:$I$2600,(ROW()-12)-$L$5-3),'Dane rozpisek'!$I$2:$I$2600,0),""))

Sheet 1
A1: ROZPISKA WÓZKÓW | C1: =IF(1<=DniMiesiaca,DATE(Rok,Miesiac,1),"") | D1: =IF(C1="","(brak dnia 1 w tym miesiącu)",CHOOSE(WEEKDAY(C1,2),"poniedziałek","wtorek","środa","czwartek","piątek","sobota","niedziela")) | E1: ROZPISKA WÓZKÓW | G1: =$C$1 | H1: =IF(G1="","(brak dnia 1 w tym miesiącu)",CHOOSE(WEEKDAY(G1,2),"poniedziałek","wtorek","środa","czwartek","piątek","sobota","niedziela")) | I1: ROZPISKA WÓZKÓW | K1: =$C$1 | L1: =IF(K1="","(brak dnia 1 w tym miesiącu)",CHOOSE(WEEKDAY(K1,2),"poniedziałek","wtorek","środa","czwartek","piątek","sobota","niedziela"))
A2: ="ZMIANA "&Ustawienia!$A$8 | C2: =Ustawienia!$B$8&"" | E2: ="ZMIANA "&Ustawienia!$A$9 | G2: =Ustawienia!$B$9&"" | I2: ="ZMIANA "&Ustawienia!$A$10 | K2: =Ustawienia!$B$10&""
A3: Specjalista zmiany: | E3: Specjalista zmiany: | I3: Specjalista zmiany:
A4: Lp | B4: Imię i nazwisko | C4: Wózek | D4: Uwagi | E4: Lp | F4: Imię i nazwisko | G4: Wózek | H4: Uwagi | I4: Lp | J4: Imię i nazwisko | K4: Wózek | L4: Uwagi
A5: =UPPER(Ustawienia!$A$14) | E5: =UPPER(Ustawienia!$A$14) | I5: =UPPER(Ustawienia!$A$14)
A6: 1 | B6: KOWALSKI JAN | C6: 105 | D6: przykład | E6: 1 | I6: 1
A7: 2 | E7: 2 | I7: 2
A8: 3 | E8: 3 | I8: 3
A9: 4 | E9: 4 | I9: 4
A10: 5 | E10: 5 | I10: 5
A11: 6 | E11: 6 | I11: 6
A12: =UPPER(Ustawienia!$A$15) | E12: =UPPER(Ustawienia!$A$15) | I12: =UPPER(Ustawienia!$A$15)
A13: 1 | E13: 1 | I13: 1
A14: 2 | E14: 2 | I14: 2
A15: 3 | E15: 3 | I15: 3
A16: 4 | E16: 4 | I16: 4
A17: 5 | E17: 5 | I17: 5
A18: 6 | E18: 6 | I18: 6
A19: 7 | E19: 7 | I19: 7
A20: 8 | E20: 8 | I20: 8
A21: =UPPER(Ustawienia!$A$16) | E21: =UPPER(Ustawienia!$A$16) | I21: =UPPER(Ustawienia!$A$16)
A22: 1 | E22: 1 | I22: 1
A23: 2 | E23: 2 | I23: 2
A24: 3 | E24: 3 | I24: 3
A25: 4 | E25: 4 | I25: 4
A26: =UPPER(Ustawienia!$A$17) | E26: =UPPER(Ustawienia!$A$17) | I26: =UPPER(Ustawienia!$A$17)
A27: 1 | E27: 1 | I27: 1
A28: 2 | E28: 2 | I28: 2
A29: 3 | E29: 3 | I29: 3
A30: 4 | E30: 4 | I30: 4
A31: =UPPER(Ustawienia!$A$18) | E31: =UPPER(Ustawienia!$A$18) | I31: =UPPER(Ustawienia!$A$18)
A32: 1 | E32: 1 | I32: 1
A33: 2 | E33: 2 | I33: 2
A34: 3 | E34: 3 | I34: 3
A35: 4 | E35: 4 | I35: 4
A36: 5 | E36: 5 | I36: 5
A38: Sporządził: ______________________ | C38: Podpis specjalisty zmiany: ________________ | E38: Sporządził: ______________________ | G38: Podpis specjalisty zmiany: ________________ | I38: Sporządził: ______________________ | K38: Podpis specjalisty zmiany: ________________

Sheet 2
A1: ROZPISKA WÓZKÓW | C1: =IF(2<=DniMiesiaca,DATE(Rok,Miesiac,2),"") | D1: =IF(C1="","(brak dnia 2 w tym miesiącu)",CHOOSE(WEEKDAY(C1,2),"poniedziałek","wtorek","środa","czwartek","piątek","sobota","niedziela")) | E1: ROZPISKA WÓZKÓW | G1: =$C$1 | H1: =IF(G1="","(brak dnia 2 w tym miesiącu)",CHOOSE(WEEKDAY(G1,2),"poniedziałek","wtorek","środa","czwartek","piątek","sobota","niedziela")) | I1: ROZPISKA WÓZKÓW | K1: =$C$1 | L1: =IF(K1="","(brak dnia 2 w tym miesiącu)",CHOOSE(WEEKDAY(K1,2),"poniedziałek","wtorek","środa","czwartek","piątek","sobota","niedziela"))
A2: ="ZMIANA "&Ustawienia!$A$8 | C2: =Ustawienia!$B$8&"" | E2: ="ZMIANA "&Ustawienia!$A$9 | G2: =Ustawienia!$B$9&"" | I2: ="ZMIANA "&Ustawienia!$A$10 | K2: =Ustawienia!$B$10&""
